2025-03-25 16:45:42,088 - INFO - Nenhum inventário encontrado.
2025-03-25 16:46:00,275 - INFO - Iniciando criação do inventário: Maria
2025-03-25 16:46:00,281 - ERROR - Erro ao criar inventário: [WinError 183] Não é possível criar um arquivo já existente: 'C:\\Users\\miqueias.silva\\Desktop\\Maria - Inserir Dados de Contagem'
2025-03-25 16:46:00,298 - INFO - 
2025-03-25 16:46:46,636 - INFO - Nenhum inventário encontrado.
2025-03-25 16:46:57,225 - INFO - Iniciando criação do inventário: Maria
2025-03-25 16:46:57,228 - INFO - Estrutura criada com sucesso em: Inventário\Maria
2025-03-25 16:46:57,228 - INFO - Pasta de contagem criada na área de trabalho: C:\Users\miqueias.silva\Desktop\Maria - Inserir Dados de Contagem
2025-03-25 16:46:57,243 - INFO - Inventários disponíveis: Maria
2025-03-25 16:46:57,254 - INFO - 
2025-03-25 16:47:07,794 - INFO - Arquivo selecionado: C:/Users/miqueias.silva/Desktop/Invent (3).txt
2025-03-25 16:47:10,810 - INFO - Iniciando processamento do arquivo: C:/Users/miqueias.silva/Desktop/Invent (3).txt
2025-03-25 16:47:19,397 - INFO - Arquivo CSV salvo em: Inventário\Maria\dados_processados\output.csv
2025-03-25 16:48:20,845 - INFO - Iniciando processamento do arquivo: C:/Users/miqueias.silva/Desktop/Invent (3).txt
2025-03-25 16:48:30,449 - INFO - Arquivo CSV salvo em: Inventário\Maria\dados_processados\output.csv
2025-03-25 16:48:46,620 - INFO - Inventários disponíveis: Maria
2025-03-25 16:48:48,578 - INFO - Iniciando consolidação para: Maria
2025-03-25 16:48:48,581 - ERROR - Erro na consolidação: Arquivo 'dados_consolidados.csv' não encontrado em Inventário\Maria\dados_processados
2025-03-25 16:48:54,940 - INFO - Inventários disponíveis: Maria
2025-03-25 16:49:16,214 - INFO - Iniciando consolidação para: Maria
2025-03-25 16:49:16,221 - ERROR - Erro na consolidação: Arquivo 'dados_consolidados.csv' não encontrado em Inventário\Maria\dados_processados
2025-03-25 16:49:18,326 - INFO - Iniciando consolidação para: Maria
2025-03-25 16:49:18,331 - ERROR - Erro na consolidação: Arquivo 'dados_consolidados.csv' não encontrado em Inventário\Maria\dados_processados
2025-03-25 16:55:55,100 - INFO - Nenhum inventário encontrado.
2025-03-25 16:56:12,517 - INFO - Iniciando criação do inventário: Athena
2025-03-25 16:56:12,521 - INFO - Estrutura criada com sucesso em: Inventário\Athena
2025-03-25 16:56:12,521 - INFO - Pasta de contagem criada na área de trabalho: C:\Users\miqueias.silva\Desktop\Athena - Inserir Dados de Contagem
2025-03-25 16:56:12,523 - INFO - Monitoramento iniciado para: C:\Users\miqueias.silva\Desktop\Athena - Inserir Dados de Contagem
2025-03-25 16:56:12,530 - INFO - Iniciando monitoramento de: C:\Users\miqueias.silva\Desktop\Athena - Inserir Dados de Contagem
2025-03-25 16:56:12,539 - INFO - 
2025-03-25 16:56:13,935 - INFO - Inventários disponíveis: Athena
2025-03-25 16:56:22,877 - INFO - Arquivo selecionado: C:/Users/miqueias.silva/Desktop/Invent.txt
2025-03-25 16:56:27,703 - INFO - Iniciando processamento do arquivo: C:/Users/miqueias.silva/Desktop/Invent.txt
2025-03-25 16:56:36,165 - INFO - Arquivo CSV salvo em: Inventário\Athena\dados_processados\output.csv
2025-03-25 17:01:27,351 - INFO - Iniciando consolidação para: Athena
2025-03-25 17:01:27,352 - ERROR - Erro na consolidação: Arquivo 'dados_consolidados.csv' não encontrado em Inventário\Athena\dados_processados
2025-03-25 17:01:42,329 - INFO - Novo arquivo detectado: C:\Users\miqueias.silva\Desktop\Athena - Inserir Dados de Contagem\teste_parte_1.xlsx
2025-03-25 17:01:42,330 - INFO - Processando arquivo: C:\Users\miqueias.silva\Desktop\Athena - Inserir Dados de Contagem\teste_parte_1.xlsx
2025-03-25 17:01:42,347 - INFO - Novo arquivo adicionado à fila: C:\Users\miqueias.silva\Desktop\Athena - Inserir Dados de Contagem\teste_parte_1.xlsx
2025-03-25 17:01:42,367 - INFO - Iniciando processamento de: C:\Users\miqueias.silva\Desktop\Athena - Inserir Dados de Contagem\teste_parte_1.xlsx
2025-03-25 17:01:43,204 - ERROR - Erro ao processar arquivo C:\Users\miqueias.silva\Desktop\Athena - Inserir Dados de Contagem\teste_parte_1.xlsx: sequence item 0: expected str instance, float found
2025-03-25 17:01:43,217 - INFO - ERRO ao processar C:\Users\miqueias.silva\Desktop\Athena - Inserir Dados de Contagem\teste_parte_1.xlsx: sequence item 0: expected str instance, float found
2025-03-25 17:01:45,792 - INFO - Iniciando consolidação para: Athena
2025-03-25 17:01:45,793 - ERROR - Erro na consolidação: Arquivo 'dados_consolidados.csv' não encontrado em Inventário\Athena\dados_processados
2025-03-25 17:01:47,696 - INFO - Iniciando consolidação para: Athena
2025-03-25 17:01:47,704 - ERROR - Erro na consolidação: Arquivo 'dados_consolidados.csv' não encontrado em Inventário\Athena\dados_processados
2025-03-25 17:03:20,593 - INFO - Monitoramento parado
2025-03-25 17:03:20,594 - INFO - Monitoramento parado
2025-03-25 17:03:25,190 - INFO - Inventários disponíveis: Athena
2025-03-25 17:13:13,014 - INFO - Nenhum inventário encontrado.
2025-03-25 17:13:32,526 - INFO - 
=== INICIANDO CRIAÇÃO DE INVENTÁRIO ===
2025-03-25 17:13:32,526 - INFO - Nome: a1
2025-03-25 17:13:32,526 - INFO - Loja: a2
2025-03-25 17:13:32,526 - INFO - Responsável: a3
2025-03-25 17:13:32,534 - INFO - Estrutura criada com sucesso em: Inventário\a1
2025-03-25 17:13:32,534 - INFO - Pasta de contagem criada na área de trabalho: C:\Users\miqueias.silva\Desktop\a1 - Inserir Dados de Contagem
2025-03-25 17:13:32,534 - INFO - Monitoramento iniciado para: C:\Users\miqueias.silva\Desktop\a1 - Inserir Dados de Contagem
2025-03-25 17:13:32,534 - INFO - 
=== MONITORAMENTO INICIADO ===
2025-03-25 17:13:32,534 - INFO - Data/Hora: 25/03/2025 17:13:32
2025-03-25 17:13:32,546 - INFO - Pasta: C:\Users\miqueias.silva\Desktop\a1 - Inserir Dados de Contagem
2025-03-25 17:13:32,547 - INFO - Inventário: a1
2025-03-25 17:13:34,862 - INFO - Inventários disponíveis: a1
2025-03-25 17:13:44,159 - INFO - Arquivo selecionado: C:/Users/miqueias.silva/Desktop/Invent.txt
2025-03-25 17:13:45,880 - INFO - 
=== INICIANDO PROCESSAMENTO ===
2025-03-25 17:13:45,884 - INFO - Arquivo: C:/Users/miqueias.silva/Desktop/Invent.txt
2025-03-25 17:13:45,884 - INFO - Destino: a1
2025-03-25 17:13:45,884 - INFO - Data/Hora: 25/03/2025 17:13:45
2025-03-25 17:13:54,701 - INFO - Arquivo CSV salvo em: Inventário\a1\dados_processados\output.csv
2025-03-25 17:14:35,571 - INFO - === PROCESSAMENTO CONCLUÍDO ===
2025-03-25 17:14:35,571 - INFO - Tempo total: 8.94 segundos
2025-03-25 17:14:35,572 - INFO - Registros processados: 1106652
2025-03-25 17:14:35,573 - INFO - Arquivo gerado: Inventário\a1\dados_processados\output.csv
2025-03-25 17:14:39,112 - INFO - 
=== INICIANDO CONSOLIDAÇÃO ===
2025-03-25 17:14:39,112 - INFO - Inventário: a1
2025-03-25 17:14:39,112 - INFO - Data/Hora: 25/03/2025 17:14:39
2025-03-25 17:14:39,122 - ERROR - ERRO: Arquivo 'dados_consolidados.csv' não encontrado em Inventário\a1\dados_processados
Traceback (most recent call last):
  File "c:\Users\miqueias.silva\Documents\HADES\main.py", line 885, in run
    raise FileNotFoundError(f"Arquivo 'dados_consolidados.csv' não encontrado em {dados_dir}")
FileNotFoundError: Arquivo 'dados_consolidados.csv' não encontrado em Inventário\a1\dados_processados

2025-03-25 17:15:03,675 - INFO - Novo arquivo detectado: C:\Users\miqueias.silva\Desktop\a1 - Inserir Dados de Contagem\teste_parte_1.xlsx
2025-03-25 17:15:03,675 - INFO - Iniciando processamento do arquivo: C:\Users\miqueias.silva\Desktop\a1 - Inserir Dados de Contagem\teste_parte_1.xlsx
2025-03-25 17:15:03,678 - INFO - 
=== INICIANDO PROCESSAMENTO ===
2025-03-25 17:15:03,679 - INFO - Arquivo: C:\Users\miqueias.silva\Desktop\a1 - Inserir Dados de Contagem\teste_parte_1.xlsx
2025-03-25 17:15:03,680 - INFO - Inventário: a1
2025-03-25 17:15:03,681 - INFO - Data/Hora: 25/03/2025 17:15:03
2025-03-25 17:15:03,681 - INFO - 
Novo arquivo detectado e adicionado à fila: C:\Users\miqueias.silva\Desktop\a1 - Inserir Dados de Contagem\teste_parte_1.xlsx
2025-03-25 17:15:04,336 - INFO - Arquivo Excel lido com sucesso
2025-03-25 17:15:04,389 - ERROR - ERRO ao processar C:\Users\miqueias.silva\Desktop\a1 - Inserir Dados de Contagem\teste_parte_1.xlsx: Erro ao processar dados: sequence item 0: expected str instance, float found
Traceback (most recent call last):
  File "c:\Users\miqueias.silva\Documents\HADES\main.py", line 599, in process_excel_file
    .agg({
     ^^^^^
  File "C:\Users\miqueias.silva\AppData\Local\Programs\Python\Python312\Lib\site-packages\pandas\core\groupby\generic.py", line 1432, in aggregate
    result = op.agg()
             ^^^^^^^^
  File "C:\Users\miqueias.silva\AppData\Local\Programs\Python\Python312\Lib\site-packages\pandas\core\apply.py", line 190, in agg
    return self.agg_dict_like()
           ^^^^^^^^^^^^^^^^^^^^
  File "C:\Users\miqueias.silva\AppData\Local\Programs\Python\Python312\Lib\site-packages\pandas\core\apply.py", line 423, in agg_dict_like
    return self.agg_or_apply_dict_like(op_name="agg")
           ^^^^^^^^^^^^^^^^^^^^^^^^^^^^^^^^^^^^^^^^^^
  File "C:\Users\miqueias.silva\AppData\Local\Programs\Python\Python312\Lib\site-packages\pandas\core\apply.py", line 1608, in agg_or_apply_dict_like
    result_index, result_data = self.compute_dict_like(
                                ^^^^^^^^^^^^^^^^^^^^^^^
  File "C:\Users\miqueias.silva\AppData\Local\Programs\Python\Python312\Lib\site-packages\pandas\core\apply.py", line 497, in compute_dict_like
    getattr(obj._gotitem(key, ndim=1), op_name)(how, **kwargs)
  File "C:\Users\miqueias.silva\AppData\Local\Programs\Python\Python312\Lib\site-packages\pandas\core\groupby\generic.py", line 291, in aggregate
    return self._python_agg_general(func, *args, **kwargs)
           ^^^^^^^^^^^^^^^^^^^^^^^^^^^^^^^^^^^^^^^^^^^^^^^
  File "C:\Users\miqueias.silva\AppData\Local\Programs\Python\Python312\Lib\site-packages\pandas\core\groupby\generic.py", line 327, in _python_agg_general
    result = self._grouper.agg_series(obj, f)
             ^^^^^^^^^^^^^^^^^^^^^^^^^^^^^^^^
  File "C:\Users\miqueias.silva\AppData\Local\Programs\Python\Python312\Lib\site-packages\pandas\core\groupby\ops.py", line 864, in agg_series
    result = self._aggregate_series_pure_python(obj, func)
             ^^^^^^^^^^^^^^^^^^^^^^^^^^^^^^^^^^^^^^^^^^^^^
  File "C:\Users\miqueias.silva\AppData\Local\Programs\Python\Python312\Lib\site-packages\pandas\core\groupby\ops.py", line 885, in _aggregate_series_pure_python
    res = func(group)
          ^^^^^^^^^^^
  File "C:\Users\miqueias.silva\AppData\Local\Programs\Python\Python312\Lib\site-packages\pandas\core\groupby\generic.py", line 324, in <lambda>
    f = lambda x: func(x, *args, **kwargs)
                  ^^^^^^^^^^^^^^^^^^^^^^^^
  File "c:\Users\miqueias.silva\Documents\HADES\main.py", line 601, in <lambda>
    "OPERADOR": lambda x: "/".join(sorted(set(x)))
                          ^^^^^^^^^^^^^^^^^^^^^^^^
TypeError: sequence item 0: expected str instance, float found

During handling of the above exception, another exception occurred:

Traceback (most recent call last):
  File "c:\Users\miqueias.silva\Documents\HADES\main.py", line 613, in process_excel_file
    raise ValueError(f"Erro ao processar dados: {str(e)}")
ValueError: Erro ao processar dados: sequence item 0: expected str instance, float found

2025-03-25 17:15:04,391 - ERROR - ERRO no processamento automático: Erro ao processar dados: sequence item 0: expected str instance, float found
Traceback (most recent call last):
  File "c:\Users\miqueias.silva\Documents\HADES\main.py", line 599, in process_excel_file
    .agg({
     ^^^^^
  File "C:\Users\miqueias.silva\AppData\Local\Programs\Python\Python312\Lib\site-packages\pandas\core\groupby\generic.py", line 1432, in aggregate
    result = op.agg()
             ^^^^^^^^
  File "C:\Users\miqueias.silva\AppData\Local\Programs\Python\Python312\Lib\site-packages\pandas\core\apply.py", line 190, in agg
    return self.agg_dict_like()
           ^^^^^^^^^^^^^^^^^^^^
  File "C:\Users\miqueias.silva\AppData\Local\Programs\Python\Python312\Lib\site-packages\pandas\core\apply.py", line 423, in agg_dict_like
    return self.agg_or_apply_dict_like(op_name="agg")
           ^^^^^^^^^^^^^^^^^^^^^^^^^^^^^^^^^^^^^^^^^^
  File "C:\Users\miqueias.silva\AppData\Local\Programs\Python\Python312\Lib\site-packages\pandas\core\apply.py", line 1608, in agg_or_apply_dict_like
    result_index, result_data = self.compute_dict_like(
                                ^^^^^^^^^^^^^^^^^^^^^^^
  File "C:\Users\miqueias.silva\AppData\Local\Programs\Python\Python312\Lib\site-packages\pandas\core\apply.py", line 497, in compute_dict_like
    getattr(obj._gotitem(key, ndim=1), op_name)(how, **kwargs)
  File "C:\Users\miqueias.silva\AppData\Local\Programs\Python\Python312\Lib\site-packages\pandas\core\groupby\generic.py", line 291, in aggregate
    return self._python_agg_general(func, *args, **kwargs)
           ^^^^^^^^^^^^^^^^^^^^^^^^^^^^^^^^^^^^^^^^^^^^^^^
  File "C:\Users\miqueias.silva\AppData\Local\Programs\Python\Python312\Lib\site-packages\pandas\core\groupby\generic.py", line 327, in _python_agg_general
    result = self._grouper.agg_series(obj, f)
             ^^^^^^^^^^^^^^^^^^^^^^^^^^^^^^^^
  File "C:\Users\miqueias.silva\AppData\Local\Programs\Python\Python312\Lib\site-packages\pandas\core\groupby\ops.py", line 864, in agg_series
    result = self._aggregate_series_pure_python(obj, func)
             ^^^^^^^^^^^^^^^^^^^^^^^^^^^^^^^^^^^^^^^^^^^^^
  File "C:\Users\miqueias.silva\AppData\Local\Programs\Python\Python312\Lib\site-packages\pandas\core\groupby\ops.py", line 885, in _aggregate_series_pure_python
    res = func(group)
          ^^^^^^^^^^^
  File "C:\Users\miqueias.silva\AppData\Local\Programs\Python\Python312\Lib\site-packages\pandas\core\groupby\generic.py", line 324, in <lambda>
    f = lambda x: func(x, *args, **kwargs)
                  ^^^^^^^^^^^^^^^^^^^^^^^^
  File "c:\Users\miqueias.silva\Documents\HADES\main.py", line 601, in <lambda>
    "OPERADOR": lambda x: "/".join(sorted(set(x)))
                          ^^^^^^^^^^^^^^^^^^^^^^^^
TypeError: sequence item 0: expected str instance, float found

During handling of the above exception, another exception occurred:

Traceback (most recent call last):
  File "c:\Users\miqueias.silva\Documents\HADES\main.py", line 533, in processor
    self.process_excel_file(file_path, inventory_name)
  File "c:\Users\miqueias.silva\Documents\HADES\main.py", line 613, in process_excel_file
    raise ValueError(f"Erro ao processar dados: {str(e)}")
ValueError: Erro ao processar dados: sequence item 0: expected str instance, float found

2025-03-25 17:15:04,391 - INFO - === ERRO NO PROCESSAMENTO ===
2025-03-25 17:15:04,393 - INFO - ERRO ao processar C:\Users\miqueias.silva\Desktop\a1 - Inserir Dados de Contagem\teste_parte_1.xlsx: Erro ao processar dados: sequence item 0: expected str instance, float found
Traceback (most recent call last):
  File "c:\Users\miqueias.silva\Documents\HADES\main.py", line 599, in process_excel_file
    .agg({
     ^^^^^
  File "C:\Users\miqueias.silva\AppData\Local\Programs\Python\Python312\Lib\site-packages\pandas\core\groupby\generic.py", line 1432, in aggregate
    result = op.agg()
             ^^^^^^^^
  File "C:\Users\miqueias.silva\AppData\Local\Programs\Python\Python312\Lib\site-packages\pandas\core\apply.py", line 190, in agg
    return self.agg_dict_like()
           ^^^^^^^^^^^^^^^^^^^^
  File "C:\Users\miqueias.silva\AppData\Local\Programs\Python\Python312\Lib\site-packages\pandas\core\apply.py", line 423, in agg_dict_like
    return self.agg_or_apply_dict_like(op_name="agg")
           ^^^^^^^^^^^^^^^^^^^^^^^^^^^^^^^^^^^^^^^^^^
  File "C:\Users\miqueias.silva\AppData\Local\Programs\Python\Python312\Lib\site-packages\pandas\core\apply.py", line 1608, in agg_or_apply_dict_like
    result_index, result_data = self.compute_dict_like(
                                ^^^^^^^^^^^^^^^^^^^^^^^
  File "C:\Users\miqueias.silva\AppData\Local\Programs\Python\Python312\Lib\site-packages\pandas\core\apply.py", line 497, in compute_dict_like
    getattr(obj._gotitem(key, ndim=1), op_name)(how, **kwargs)
  File "C:\Users\miqueias.silva\AppData\Local\Programs\Python\Python312\Lib\site-packages\pandas\core\groupby\generic.py", line 291, in aggregate
    return self._python_agg_general(func, *args, **kwargs)
           ^^^^^^^^^^^^^^^^^^^^^^^^^^^^^^^^^^^^^^^^^^^^^^^
  File "C:\Users\miqueias.silva\AppData\Local\Programs\Python\Python312\Lib\site-packages\pandas\core\groupby\generic.py", line 327, in _python_agg_general
    result = self._grouper.agg_series(obj, f)
             ^^^^^^^^^^^^^^^^^^^^^^^^^^^^^^^^
  File "C:\Users\miqueias.silva\AppData\Local\Programs\Python\Python312\Lib\site-packages\pandas\core\groupby\ops.py", line 864, in agg_series
    result = self._aggregate_series_pure_python(obj, func)
             ^^^^^^^^^^^^^^^^^^^^^^^^^^^^^^^^^^^^^^^^^^^^^
  File "C:\Users\miqueias.silva\AppData\Local\Programs\Python\Python312\Lib\site-packages\pandas\core\groupby\ops.py", line 885, in _aggregate_series_pure_python
    res = func(group)
          ^^^^^^^^^^^
  File "C:\Users\miqueias.silva\AppData\Local\Programs\Python\Python312\Lib\site-packages\pandas\core\groupby\generic.py", line 324, in <lambda>
    f = lambda x: func(x, *args, **kwargs)
                  ^^^^^^^^^^^^^^^^^^^^^^^^
  File "c:\Users\miqueias.silva\Documents\HADES\main.py", line 601, in <lambda>
    "OPERADOR": lambda x: "/".join(sorted(set(x)))
                          ^^^^^^^^^^^^^^^^^^^^^^^^
TypeError: sequence item 0: expected str instance, float found

During handling of the above exception, another exception occurred:

Traceback (most recent call last):
  File "c:\Users\miqueias.silva\Documents\HADES\main.py", line 613, in process_excel_file
    raise ValueError(f"Erro ao processar dados: {str(e)}")
ValueError: Erro ao processar dados: sequence item 0: expected str instance, float found

2025-03-25 17:15:04,393 - INFO - 
=== ERRO NO PROCESSAMENTO AUTOMÁTICO ===
2025-03-25 17:15:04,398 - INFO - ERRO no processamento automático: Erro ao processar dados: sequence item 0: expected str instance, float found
Traceback (most recent call last):
  File "c:\Users\miqueias.silva\Documents\HADES\main.py", line 599, in process_excel_file
    .agg({
     ^^^^^
  File "C:\Users\miqueias.silva\AppData\Local\Programs\Python\Python312\Lib\site-packages\pandas\core\groupby\generic.py", line 1432, in aggregate
    result = op.agg()
             ^^^^^^^^
  File "C:\Users\miqueias.silva\AppData\Local\Programs\Python\Python312\Lib\site-packages\pandas\core\apply.py", line 190, in agg
    return self.agg_dict_like()
           ^^^^^^^^^^^^^^^^^^^^
  File "C:\Users\miqueias.silva\AppData\Local\Programs\Python\Python312\Lib\site-packages\pandas\core\apply.py", line 423, in agg_dict_like
    return self.agg_or_apply_dict_like(op_name="agg")
           ^^^^^^^^^^^^^^^^^^^^^^^^^^^^^^^^^^^^^^^^^^
  File "C:\Users\miqueias.silva\AppData\Local\Programs\Python\Python312\Lib\site-packages\pandas\core\apply.py", line 1608, in agg_or_apply_dict_like
    result_index, result_data = self.compute_dict_like(
                                ^^^^^^^^^^^^^^^^^^^^^^^
  File "C:\Users\miqueias.silva\AppData\Local\Programs\Python\Python312\Lib\site-packages\pandas\core\apply.py", line 497, in compute_dict_like
    getattr(obj._gotitem(key, ndim=1), op_name)(how, **kwargs)
  File "C:\Users\miqueias.silva\AppData\Local\Programs\Python\Python312\Lib\site-packages\pandas\core\groupby\generic.py", line 291, in aggregate
    return self._python_agg_general(func, *args, **kwargs)
           ^^^^^^^^^^^^^^^^^^^^^^^^^^^^^^^^^^^^^^^^^^^^^^^
  File "C:\Users\miqueias.silva\AppData\Local\Programs\Python\Python312\Lib\site-packages\pandas\core\groupby\generic.py", line 327, in _python_agg_general
    result = self._grouper.agg_series(obj, f)
             ^^^^^^^^^^^^^^^^^^^^^^^^^^^^^^^^
  File "C:\Users\miqueias.silva\AppData\Local\Programs\Python\Python312\Lib\site-packages\pandas\core\groupby\ops.py", line 864, in agg_series
    result = self._aggregate_series_pure_python(obj, func)
             ^^^^^^^^^^^^^^^^^^^^^^^^^^^^^^^^^^^^^^^^^^^^^
  File "C:\Users\miqueias.silva\AppData\Local\Programs\Python\Python312\Lib\site-packages\pandas\core\groupby\ops.py", line 885, in _aggregate_series_pure_python
    res = func(group)
          ^^^^^^^^^^^
  File "C:\Users\miqueias.silva\AppData\Local\Programs\Python\Python312\Lib\site-packages\pandas\core\groupby\generic.py", line 324, in <lambda>
    f = lambda x: func(x, *args, **kwargs)
                  ^^^^^^^^^^^^^^^^^^^^^^^^
  File "c:\Users\miqueias.silva\Documents\HADES\main.py", line 601, in <lambda>
    "OPERADOR": lambda x: "/".join(sorted(set(x)))
                          ^^^^^^^^^^^^^^^^^^^^^^^^
TypeError: sequence item 0: expected str instance, float found

During handling of the above exception, another exception occurred:

Traceback (most recent call last):
  File "c:\Users\miqueias.silva\Documents\HADES\main.py", line 533, in processor
    self.process_excel_file(file_path, inventory_name)
  File "c:\Users\miqueias.silva\Documents\HADES\main.py", line 613, in process_excel_file
    raise ValueError(f"Erro ao processar dados: {str(e)}")
ValueError: Erro ao processar dados: sequence item 0: expected str instance, float found

2025-03-25 17:15:53,567 - INFO - Inventários disponíveis: a1
2025-03-25 17:16:25,469 - INFO - 
=== INICIANDO CRIAÇÃO DE INVENTÁRIO ===
2025-03-25 17:16:25,476 - INFO - Nome: a2
2025-03-25 17:16:25,477 - INFO - Loja: a2
2025-03-25 17:16:25,478 - INFO - Responsável: a2
2025-03-25 17:16:25,482 - INFO - Estrutura criada com sucesso em: Inventário\a2
2025-03-25 17:16:25,482 - INFO - Pasta de contagem criada na área de trabalho: C:\Users\miqueias.silva\Desktop\a2 - Inserir Dados de Contagem
2025-03-25 17:16:25,484 - INFO - Monitoramento iniciado para: C:\Users\miqueias.silva\Desktop\a2 - Inserir Dados de Contagem
2025-03-25 17:16:25,488 - INFO - 
=== MONITORAMENTO INICIADO ===
2025-03-25 17:16:25,492 - INFO - Data/Hora: 25/03/2025 17:16:25
2025-03-25 17:16:25,497 - INFO - Pasta: C:\Users\miqueias.silva\Desktop\a2 - Inserir Dados de Contagem
2025-03-25 17:16:25,500 - INFO - Inventário: a2
2025-03-25 17:16:26,593 - INFO - Inventários disponíveis: a1, a2
2025-03-25 17:16:33,814 - INFO - Arquivo selecionado: C:/Users/miqueias.silva/Desktop/Invent.txt
2025-03-25 17:16:35,432 - INFO - 
=== INICIANDO PROCESSAMENTO ===
2025-03-25 17:16:35,437 - INFO - Arquivo: C:/Users/miqueias.silva/Desktop/Invent.txt
2025-03-25 17:16:35,438 - INFO - Destino: a1
2025-03-25 17:16:35,438 - INFO - Data/Hora: 25/03/2025 17:16:35
2025-03-25 17:16:50,762 - INFO - Arquivo CSV salvo em: Inventário\a1\dados_processados\output.csv
2025-03-25 17:16:52,158 - INFO - === PROCESSAMENTO CONCLUÍDO ===
2025-03-25 17:16:52,160 - INFO - Tempo total: 15.32 segundos
2025-03-25 17:16:52,160 - INFO - Registros processados: 1106652
2025-03-25 17:16:52,161 - INFO - Arquivo gerado: Inventário\a1\dados_processados\output.csv
2025-03-25 17:16:53,980 - INFO - 
=== INICIANDO CONSOLIDAÇÃO ===
2025-03-25 17:16:53,981 - INFO - Inventário: a1
2025-03-25 17:16:53,981 - INFO - Data/Hora: 25/03/2025 17:16:53
2025-03-25 17:16:53,985 - ERROR - ERRO: Arquivo 'dados_consolidados.csv' não encontrado em Inventário\a1\dados_processados
Traceback (most recent call last):
  File "C:\Users\miqueias.silva\Documents\HADES\main.py", line 885, in run
    raise FileNotFoundError(f"Arquivo 'dados_consolidados.csv' não encontrado em {dados_dir}")
FileNotFoundError: Arquivo 'dados_consolidados.csv' não encontrado em Inventário\a1\dados_processados

2025-03-25 17:17:07,907 - INFO - Novo arquivo detectado: C:\Users\miqueias.silva\Desktop\a2 - Inserir Dados de Contagem\teste_parte_1.xlsx
2025-03-25 17:17:07,907 - INFO - Iniciando processamento do arquivo: C:\Users\miqueias.silva\Desktop\a2 - Inserir Dados de Contagem\teste_parte_1.xlsx
2025-03-25 17:17:07,907 - INFO - 
=== INICIANDO PROCESSAMENTO ===
2025-03-25 17:17:07,907 - INFO - Arquivo: C:\Users\miqueias.silva\Desktop\a2 - Inserir Dados de Contagem\teste_parte_1.xlsx
2025-03-25 17:17:07,916 - INFO - Inventário: a2
2025-03-25 17:17:07,916 - INFO - Data/Hora: 25/03/2025 17:17:07
2025-03-25 17:17:07,916 - INFO - 
Novo arquivo detectado e adicionado à fila: C:\Users\miqueias.silva\Desktop\a2 - Inserir Dados de Contagem\teste_parte_1.xlsx
2025-03-25 17:17:08,671 - INFO - Arquivo Excel lido com sucesso
2025-03-25 17:17:08,684 - ERROR - ERRO ao processar C:\Users\miqueias.silva\Desktop\a2 - Inserir Dados de Contagem\teste_parte_1.xlsx: Erro ao processar dados: sequence item 0: expected str instance, float found
Traceback (most recent call last):
  File "C:\Users\miqueias.silva\Documents\HADES\main.py", line 599, in process_excel_file
    .agg({
     ^^^^^
  File "c:\Users\miqueias.silva\AppData\Local\Programs\Python\Python312\Lib\site-packages\pandas\core\groupby\generic.py", line 1432, in aggregate
    result = op.agg()
             ^^^^^^^^
  File "c:\Users\miqueias.silva\AppData\Local\Programs\Python\Python312\Lib\site-packages\pandas\core\apply.py", line 190, in agg
    return self.agg_dict_like()
           ^^^^^^^^^^^^^^^^^^^^
  File "c:\Users\miqueias.silva\AppData\Local\Programs\Python\Python312\Lib\site-packages\pandas\core\apply.py", line 423, in agg_dict_like
    return self.agg_or_apply_dict_like(op_name="agg")
           ^^^^^^^^^^^^^^^^^^^^^^^^^^^^^^^^^^^^^^^^^^
  File "c:\Users\miqueias.silva\AppData\Local\Programs\Python\Python312\Lib\site-packages\pandas\core\apply.py", line 1608, in agg_or_apply_dict_like
    result_index, result_data = self.compute_dict_like(
                                ^^^^^^^^^^^^^^^^^^^^^^^
  File "c:\Users\miqueias.silva\AppData\Local\Programs\Python\Python312\Lib\site-packages\pandas\core\apply.py", line 497, in compute_dict_like
    getattr(obj._gotitem(key, ndim=1), op_name)(how, **kwargs)
  File "c:\Users\miqueias.silva\AppData\Local\Programs\Python\Python312\Lib\site-packages\pandas\core\groupby\generic.py", line 291, in aggregate
    return self._python_agg_general(func, *args, **kwargs)
           ^^^^^^^^^^^^^^^^^^^^^^^^^^^^^^^^^^^^^^^^^^^^^^^
  File "c:\Users\miqueias.silva\AppData\Local\Programs\Python\Python312\Lib\site-packages\pandas\core\groupby\generic.py", line 327, in _python_agg_general
    result = self._grouper.agg_series(obj, f)
             ^^^^^^^^^^^^^^^^^^^^^^^^^^^^^^^^
  File "c:\Users\miqueias.silva\AppData\Local\Programs\Python\Python312\Lib\site-packages\pandas\core\groupby\ops.py", line 864, in agg_series
    result = self._aggregate_series_pure_python(obj, func)
             ^^^^^^^^^^^^^^^^^^^^^^^^^^^^^^^^^^^^^^^^^^^^^
  File "c:\Users\miqueias.silva\AppData\Local\Programs\Python\Python312\Lib\site-packages\pandas\core\groupby\ops.py", line 885, in _aggregate_series_pure_python
    res = func(group)
          ^^^^^^^^^^^
  File "c:\Users\miqueias.silva\AppData\Local\Programs\Python\Python312\Lib\site-packages\pandas\core\groupby\generic.py", line 324, in <lambda>
    f = lambda x: func(x, *args, **kwargs)
                  ^^^^^^^^^^^^^^^^^^^^^^^^
  File "C:\Users\miqueias.silva\Documents\HADES\main.py", line 601, in <lambda>
    "OPERADOR": lambda x: "/".join(sorted(set(x)))
                          ^^^^^^^^^^^^^^^^^^^^^^^^
TypeError: sequence item 0: expected str instance, float found

During handling of the above exception, another exception occurred:

Traceback (most recent call last):
  File "C:\Users\miqueias.silva\Documents\HADES\main.py", line 613, in process_excel_file
    raise ValueError(f"Erro ao processar dados: {str(e)}")
ValueError: Erro ao processar dados: sequence item 0: expected str instance, float found

2025-03-25 17:17:08,684 - ERROR - ERRO no processamento automático: Erro ao processar dados: sequence item 0: expected str instance, float found
Traceback (most recent call last):
  File "C:\Users\miqueias.silva\Documents\HADES\main.py", line 599, in process_excel_file
    .agg({
     ^^^^^
  File "c:\Users\miqueias.silva\AppData\Local\Programs\Python\Python312\Lib\site-packages\pandas\core\groupby\generic.py", line 1432, in aggregate
    result = op.agg()
             ^^^^^^^^
  File "c:\Users\miqueias.silva\AppData\Local\Programs\Python\Python312\Lib\site-packages\pandas\core\apply.py", line 190, in agg
    return self.agg_dict_like()
           ^^^^^^^^^^^^^^^^^^^^
  File "c:\Users\miqueias.silva\AppData\Local\Programs\Python\Python312\Lib\site-packages\pandas\core\apply.py", line 423, in agg_dict_like
    return self.agg_or_apply_dict_like(op_name="agg")
           ^^^^^^^^^^^^^^^^^^^^^^^^^^^^^^^^^^^^^^^^^^
  File "c:\Users\miqueias.silva\AppData\Local\Programs\Python\Python312\Lib\site-packages\pandas\core\apply.py", line 1608, in agg_or_apply_dict_like
    result_index, result_data = self.compute_dict_like(
                                ^^^^^^^^^^^^^^^^^^^^^^^
  File "c:\Users\miqueias.silva\AppData\Local\Programs\Python\Python312\Lib\site-packages\pandas\core\apply.py", line 497, in compute_dict_like
    getattr(obj._gotitem(key, ndim=1), op_name)(how, **kwargs)
  File "c:\Users\miqueias.silva\AppData\Local\Programs\Python\Python312\Lib\site-packages\pandas\core\groupby\generic.py", line 291, in aggregate
    return self._python_agg_general(func, *args, **kwargs)
           ^^^^^^^^^^^^^^^^^^^^^^^^^^^^^^^^^^^^^^^^^^^^^^^
  File "c:\Users\miqueias.silva\AppData\Local\Programs\Python\Python312\Lib\site-packages\pandas\core\groupby\generic.py", line 327, in _python_agg_general
    result = self._grouper.agg_series(obj, f)
             ^^^^^^^^^^^^^^^^^^^^^^^^^^^^^^^^
  File "c:\Users\miqueias.silva\AppData\Local\Programs\Python\Python312\Lib\site-packages\pandas\core\groupby\ops.py", line 864, in agg_series
    result = self._aggregate_series_pure_python(obj, func)
             ^^^^^^^^^^^^^^^^^^^^^^^^^^^^^^^^^^^^^^^^^^^^^
  File "c:\Users\miqueias.silva\AppData\Local\Programs\Python\Python312\Lib\site-packages\pandas\core\groupby\ops.py", line 885, in _aggregate_series_pure_python
    res = func(group)
          ^^^^^^^^^^^
  File "c:\Users\miqueias.silva\AppData\Local\Programs\Python\Python312\Lib\site-packages\pandas\core\groupby\generic.py", line 324, in <lambda>
    f = lambda x: func(x, *args, **kwargs)
                  ^^^^^^^^^^^^^^^^^^^^^^^^
  File "C:\Users\miqueias.silva\Documents\HADES\main.py", line 601, in <lambda>
    "OPERADOR": lambda x: "/".join(sorted(set(x)))
                          ^^^^^^^^^^^^^^^^^^^^^^^^
TypeError: sequence item 0: expected str instance, float found

During handling of the above exception, another exception occurred:

Traceback (most recent call last):
  File "C:\Users\miqueias.silva\Documents\HADES\main.py", line 533, in processor
    self.process_excel_file(file_path, inventory_name)
  File "C:\Users\miqueias.silva\Documents\HADES\main.py", line 613, in process_excel_file
    raise ValueError(f"Erro ao processar dados: {str(e)}")
ValueError: Erro ao processar dados: sequence item 0: expected str instance, float found

2025-03-25 17:17:08,684 - INFO - === ERRO NO PROCESSAMENTO ===
2025-03-25 17:17:08,697 - INFO - ERRO ao processar C:\Users\miqueias.silva\Desktop\a2 - Inserir Dados de Contagem\teste_parte_1.xlsx: Erro ao processar dados: sequence item 0: expected str instance, float found
Traceback (most recent call last):
  File "C:\Users\miqueias.silva\Documents\HADES\main.py", line 599, in process_excel_file
    .agg({
     ^^^^^
  File "c:\Users\miqueias.silva\AppData\Local\Programs\Python\Python312\Lib\site-packages\pandas\core\groupby\generic.py", line 1432, in aggregate
    result = op.agg()
             ^^^^^^^^
  File "c:\Users\miqueias.silva\AppData\Local\Programs\Python\Python312\Lib\site-packages\pandas\core\apply.py", line 190, in agg
    return self.agg_dict_like()
           ^^^^^^^^^^^^^^^^^^^^
  File "c:\Users\miqueias.silva\AppData\Local\Programs\Python\Python312\Lib\site-packages\pandas\core\apply.py", line 423, in agg_dict_like
    return self.agg_or_apply_dict_like(op_name="agg")
           ^^^^^^^^^^^^^^^^^^^^^^^^^^^^^^^^^^^^^^^^^^
  File "c:\Users\miqueias.silva\AppData\Local\Programs\Python\Python312\Lib\site-packages\pandas\core\apply.py", line 1608, in agg_or_apply_dict_like
    result_index, result_data = self.compute_dict_like(
                                ^^^^^^^^^^^^^^^^^^^^^^^
  File "c:\Users\miqueias.silva\AppData\Local\Programs\Python\Python312\Lib\site-packages\pandas\core\apply.py", line 497, in compute_dict_like
    getattr(obj._gotitem(key, ndim=1), op_name)(how, **kwargs)
  File "c:\Users\miqueias.silva\AppData\Local\Programs\Python\Python312\Lib\site-packages\pandas\core\groupby\generic.py", line 291, in aggregate
    return self._python_agg_general(func, *args, **kwargs)
           ^^^^^^^^^^^^^^^^^^^^^^^^^^^^^^^^^^^^^^^^^^^^^^^
  File "c:\Users\miqueias.silva\AppData\Local\Programs\Python\Python312\Lib\site-packages\pandas\core\groupby\generic.py", line 327, in _python_agg_general
    result = self._grouper.agg_series(obj, f)
             ^^^^^^^^^^^^^^^^^^^^^^^^^^^^^^^^
  File "c:\Users\miqueias.silva\AppData\Local\Programs\Python\Python312\Lib\site-packages\pandas\core\groupby\ops.py", line 864, in agg_series
    result = self._aggregate_series_pure_python(obj, func)
             ^^^^^^^^^^^^^^^^^^^^^^^^^^^^^^^^^^^^^^^^^^^^^
  File "c:\Users\miqueias.silva\AppData\Local\Programs\Python\Python312\Lib\site-packages\pandas\core\groupby\ops.py", line 885, in _aggregate_series_pure_python
    res = func(group)
          ^^^^^^^^^^^
  File "c:\Users\miqueias.silva\AppData\Local\Programs\Python\Python312\Lib\site-packages\pandas\core\groupby\generic.py", line 324, in <lambda>
    f = lambda x: func(x, *args, **kwargs)
                  ^^^^^^^^^^^^^^^^^^^^^^^^
  File "C:\Users\miqueias.silva\Documents\HADES\main.py", line 601, in <lambda>
    "OPERADOR": lambda x: "/".join(sorted(set(x)))
                          ^^^^^^^^^^^^^^^^^^^^^^^^
TypeError: sequence item 0: expected str instance, float found

During handling of the above exception, another exception occurred:

Traceback (most recent call last):
  File "C:\Users\miqueias.silva\Documents\HADES\main.py", line 613, in process_excel_file
    raise ValueError(f"Erro ao processar dados: {str(e)}")
ValueError: Erro ao processar dados: sequence item 0: expected str instance, float found

2025-03-25 17:17:08,697 - INFO - 
=== ERRO NO PROCESSAMENTO AUTOMÁTICO ===
2025-03-25 17:17:08,697 - INFO - ERRO no processamento automático: Erro ao processar dados: sequence item 0: expected str instance, float found
Traceback (most recent call last):
  File "C:\Users\miqueias.silva\Documents\HADES\main.py", line 599, in process_excel_file
    .agg({
     ^^^^^
  File "c:\Users\miqueias.silva\AppData\Local\Programs\Python\Python312\Lib\site-packages\pandas\core\groupby\generic.py", line 1432, in aggregate
    result = op.agg()
             ^^^^^^^^
  File "c:\Users\miqueias.silva\AppData\Local\Programs\Python\Python312\Lib\site-packages\pandas\core\apply.py", line 190, in agg
    return self.agg_dict_like()
           ^^^^^^^^^^^^^^^^^^^^
  File "c:\Users\miqueias.silva\AppData\Local\Programs\Python\Python312\Lib\site-packages\pandas\core\apply.py", line 423, in agg_dict_like
    return self.agg_or_apply_dict_like(op_name="agg")
           ^^^^^^^^^^^^^^^^^^^^^^^^^^^^^^^^^^^^^^^^^^
  File "c:\Users\miqueias.silva\AppData\Local\Programs\Python\Python312\Lib\site-packages\pandas\core\apply.py", line 1608, in agg_or_apply_dict_like
    result_index, result_data = self.compute_dict_like(
                                ^^^^^^^^^^^^^^^^^^^^^^^
  File "c:\Users\miqueias.silva\AppData\Local\Programs\Python\Python312\Lib\site-packages\pandas\core\apply.py", line 497, in compute_dict_like
    getattr(obj._gotitem(key, ndim=1), op_name)(how, **kwargs)
  File "c:\Users\miqueias.silva\AppData\Local\Programs\Python\Python312\Lib\site-packages\pandas\core\groupby\generic.py", line 291, in aggregate
    return self._python_agg_general(func, *args, **kwargs)
           ^^^^^^^^^^^^^^^^^^^^^^^^^^^^^^^^^^^^^^^^^^^^^^^
  File "c:\Users\miqueias.silva\AppData\Local\Programs\Python\Python312\Lib\site-packages\pandas\core\groupby\generic.py", line 327, in _python_agg_general
    result = self._grouper.agg_series(obj, f)
             ^^^^^^^^^^^^^^^^^^^^^^^^^^^^^^^^
  File "c:\Users\miqueias.silva\AppData\Local\Programs\Python\Python312\Lib\site-packages\pandas\core\groupby\ops.py", line 864, in agg_series
    result = self._aggregate_series_pure_python(obj, func)
             ^^^^^^^^^^^^^^^^^^^^^^^^^^^^^^^^^^^^^^^^^^^^^
  File "c:\Users\miqueias.silva\AppData\Local\Programs\Python\Python312\Lib\site-packages\pandas\core\groupby\ops.py", line 885, in _aggregate_series_pure_python
    res = func(group)
          ^^^^^^^^^^^
  File "c:\Users\miqueias.silva\AppData\Local\Programs\Python\Python312\Lib\site-packages\pandas\core\groupby\generic.py", line 324, in <lambda>
    f = lambda x: func(x, *args, **kwargs)
                  ^^^^^^^^^^^^^^^^^^^^^^^^
  File "C:\Users\miqueias.silva\Documents\HADES\main.py", line 601, in <lambda>
    "OPERADOR": lambda x: "/".join(sorted(set(x)))
                          ^^^^^^^^^^^^^^^^^^^^^^^^
TypeError: sequence item 0: expected str instance, float found

During handling of the above exception, another exception occurred:

Traceback (most recent call last):
  File "C:\Users\miqueias.silva\Documents\HADES\main.py", line 533, in processor
    self.process_excel_file(file_path, inventory_name)
  File "C:\Users\miqueias.silva\Documents\HADES\main.py", line 613, in process_excel_file
    raise ValueError(f"Erro ao processar dados: {str(e)}")
ValueError: Erro ao processar dados: sequence item 0: expected str instance, float found

2025-03-25 17:17:22,419 - INFO - Inventários disponíveis: a1, a2
2025-03-25 17:17:27,258 - INFO - 
=== INICIANDO CRIAÇÃO DE INVENTÁRIO ===
2025-03-25 17:17:27,258 - INFO - Nome: a3
2025-03-25 17:17:27,258 - INFO - Loja: a3
2025-03-25 17:17:27,258 - INFO - Responsável: a3
2025-03-25 17:17:27,258 - INFO - Estrutura criada com sucesso em: Inventário\a3
2025-03-25 17:17:27,258 - INFO - Pasta de contagem criada na área de trabalho: C:\Users\miqueias.silva\Desktop\a3 - Inserir Dados de Contagem
2025-03-25 17:17:27,267 - INFO - Monitoramento iniciado para: C:\Users\miqueias.silva\Desktop\a3 - Inserir Dados de Contagem
2025-03-25 17:17:27,272 - INFO - 
=== MONITORAMENTO INICIADO ===
2025-03-25 17:17:27,273 - INFO - Data/Hora: 25/03/2025 17:17:27
2025-03-25 17:17:27,277 - INFO - Pasta: C:\Users\miqueias.silva\Desktop\a3 - Inserir Dados de Contagem
2025-03-25 17:17:27,279 - INFO - Inventário: a3
2025-03-25 17:17:28,238 - INFO - Inventários disponíveis: a1, a2, a3
2025-03-25 17:17:34,596 - INFO - Arquivo selecionado: C:/Users/miqueias.silva/Desktop/Invent (3).txt
2025-03-25 17:17:35,131 - INFO - 
=== INICIANDO PROCESSAMENTO ===
2025-03-25 17:17:35,131 - INFO - Arquivo: C:/Users/miqueias.silva/Desktop/Invent (3).txt
2025-03-25 17:17:35,131 - INFO - Destino: a1
2025-03-25 17:17:35,131 - INFO - Data/Hora: 25/03/2025 17:17:35
2025-03-25 17:17:48,286 - INFO - Arquivo CSV salvo em: Inventário\a1\dados_processados\output.csv
2025-03-25 17:17:51,977 - INFO - === PROCESSAMENTO CONCLUÍDO ===
2025-03-25 17:17:51,978 - INFO - Tempo total: 13.16 segundos
2025-03-25 17:17:51,978 - INFO - Registros processados: 1106652
2025-03-25 17:17:51,978 - INFO - Arquivo gerado: Inventário\a1\dados_processados\output.csv
2025-03-25 17:17:55,707 - INFO - Inventários disponíveis: a1, a2, a3
2025-03-25 17:17:58,210 - INFO - 
=== INICIANDO PROCESSAMENTO ===
2025-03-25 17:17:58,210 - INFO - Arquivo: C:/Users/miqueias.silva/Desktop/Invent (3).txt
2025-03-25 17:17:58,210 - INFO - Destino: a1
2025-03-25 17:17:58,226 - INFO - Data/Hora: 25/03/2025 17:17:58
2025-03-25 17:18:07,069 - INFO - Inventários disponíveis: a1, a2, a3
2025-03-25 17:18:07,800 - INFO - Arquivo CSV salvo em: Inventário\a1\dados_processados\output.csv
2025-03-25 17:18:09,952 - INFO - === PROCESSAMENTO CONCLUÍDO ===
2025-03-25 17:18:09,952 - INFO - Tempo total: 9.57 segundos
2025-03-25 17:18:09,952 - INFO - Registros processados: 1106652
2025-03-25 17:18:09,952 - INFO - Arquivo gerado: Inventário\a1\dados_processados\output.csv
2025-03-25 17:18:13,571 - INFO - 
=== INICIANDO PROCESSAMENTO ===
2025-03-25 17:18:13,571 - INFO - Arquivo: C:/Users/miqueias.silva/Desktop/Invent (3).txt
2025-03-25 17:18:13,571 - INFO - Destino: a3
2025-03-25 17:18:13,571 - INFO - Data/Hora: 25/03/2025 17:18:13
2025-03-25 17:18:16,975 - INFO - 
=== INICIANDO CONSOLIDAÇÃO ===
2025-03-25 17:18:16,975 - INFO - Inventário: a3
2025-03-25 17:18:16,975 - INFO - Data/Hora: 25/03/2025 17:18:16
2025-03-25 17:18:16,989 - ERROR - ERRO: Arquivo 'output.csv' não encontrado em Inventário\a3\dados_processados
Traceback (most recent call last):
  File "C:\Users\miqueias.silva\Documents\HADES\main.py", line 883, in run
    raise FileNotFoundError(f"Arquivo 'output.csv' não encontrado em {dados_dir}")
FileNotFoundError: Arquivo 'output.csv' não encontrado em Inventário\a3\dados_processados

2025-03-25 17:18:18,747 - INFO - === ERRO NA CONSOLIDAÇÃO ===
2025-03-25 17:18:19,298 - INFO - ERRO: Arquivo 'output.csv' não encontrado em Inventário\a3\dados_processados
Traceback (most recent call last):
  File "C:\Users\miqueias.silva\Documents\HADES\main.py", line 883, in run
    raise FileNotFoundError(f"Arquivo 'output.csv' não encontrado em {dados_dir}")
FileNotFoundError: Arquivo 'output.csv' não encontrado em Inventário\a3\dados_processados

2025-03-25 17:18:21,509 - INFO - Novo arquivo detectado: C:\Users\miqueias.silva\Desktop\a3 - Inserir Dados de Contagem\teste.xlsx
2025-03-25 17:18:21,509 - INFO - Iniciando processamento do arquivo: C:\Users\miqueias.silva\Desktop\a3 - Inserir Dados de Contagem\teste.xlsx
2025-03-25 17:18:21,528 - INFO - 
=== INICIANDO PROCESSAMENTO ===
2025-03-25 17:18:21,536 - INFO - Arquivo: C:\Users\miqueias.silva\Desktop\a3 - Inserir Dados de Contagem\teste.xlsx
2025-03-25 17:18:21,539 - INFO - Inventário: a3
2025-03-25 17:18:21,543 - INFO - Data/Hora: 25/03/2025 17:18:21
2025-03-25 17:18:21,546 - INFO - 
Novo arquivo detectado e adicionado à fila: C:\Users\miqueias.silva\Desktop\a3 - Inserir Dados de Contagem\teste.xlsx
2025-03-25 17:18:24,764 - INFO - Arquivo Excel lido com sucesso
2025-03-25 17:18:24,856 - ERROR - ERRO ao processar C:\Users\miqueias.silva\Desktop\a3 - Inserir Dados de Contagem\teste.xlsx: Erro ao processar dados: sequence item 0: expected str instance, float found
Traceback (most recent call last):
  File "C:\Users\miqueias.silva\Documents\HADES\main.py", line 599, in process_excel_file
    .agg({
     ^^^^^
  File "c:\Users\miqueias.silva\AppData\Local\Programs\Python\Python312\Lib\site-packages\pandas\core\groupby\generic.py", line 1432, in aggregate
    result = op.agg()
             ^^^^^^^^
  File "c:\Users\miqueias.silva\AppData\Local\Programs\Python\Python312\Lib\site-packages\pandas\core\apply.py", line 190, in agg
    return self.agg_dict_like()
           ^^^^^^^^^^^^^^^^^^^^
  File "c:\Users\miqueias.silva\AppData\Local\Programs\Python\Python312\Lib\site-packages\pandas\core\apply.py", line 423, in agg_dict_like
    return self.agg_or_apply_dict_like(op_name="agg")
           ^^^^^^^^^^^^^^^^^^^^^^^^^^^^^^^^^^^^^^^^^^
  File "c:\Users\miqueias.silva\AppData\Local\Programs\Python\Python312\Lib\site-packages\pandas\core\apply.py", line 1608, in agg_or_apply_dict_like
    result_index, result_data = self.compute_dict_like(
                                ^^^^^^^^^^^^^^^^^^^^^^^
  File "c:\Users\miqueias.silva\AppData\Local\Programs\Python\Python312\Lib\site-packages\pandas\core\apply.py", line 497, in compute_dict_like
    getattr(obj._gotitem(key, ndim=1), op_name)(how, **kwargs)
  File "c:\Users\miqueias.silva\AppData\Local\Programs\Python\Python312\Lib\site-packages\pandas\core\groupby\generic.py", line 291, in aggregate
    return self._python_agg_general(func, *args, **kwargs)
           ^^^^^^^^^^^^^^^^^^^^^^^^^^^^^^^^^^^^^^^^^^^^^^^
  File "c:\Users\miqueias.silva\AppData\Local\Programs\Python\Python312\Lib\site-packages\pandas\core\groupby\generic.py", line 327, in _python_agg_general
    result = self._grouper.agg_series(obj, f)
             ^^^^^^^^^^^^^^^^^^^^^^^^^^^^^^^^
  File "c:\Users\miqueias.silva\AppData\Local\Programs\Python\Python312\Lib\site-packages\pandas\core\groupby\ops.py", line 864, in agg_series
    result = self._aggregate_series_pure_python(obj, func)
             ^^^^^^^^^^^^^^^^^^^^^^^^^^^^^^^^^^^^^^^^^^^^^
  File "c:\Users\miqueias.silva\AppData\Local\Programs\Python\Python312\Lib\site-packages\pandas\core\groupby\ops.py", line 885, in _aggregate_series_pure_python
    res = func(group)
          ^^^^^^^^^^^
  File "c:\Users\miqueias.silva\AppData\Local\Programs\Python\Python312\Lib\site-packages\pandas\core\groupby\generic.py", line 324, in <lambda>
    f = lambda x: func(x, *args, **kwargs)
                  ^^^^^^^^^^^^^^^^^^^^^^^^
  File "C:\Users\miqueias.silva\Documents\HADES\main.py", line 601, in <lambda>
    "OPERADOR": lambda x: "/".join(sorted(set(x)))
                          ^^^^^^^^^^^^^^^^^^^^^^^^
TypeError: sequence item 0: expected str instance, float found

During handling of the above exception, another exception occurred:

Traceback (most recent call last):
  File "C:\Users\miqueias.silva\Documents\HADES\main.py", line 613, in process_excel_file
    raise ValueError(f"Erro ao processar dados: {str(e)}")
ValueError: Erro ao processar dados: sequence item 0: expected str instance, float found

2025-03-25 17:18:24,856 - INFO - === ERRO NO PROCESSAMENTO ===
2025-03-25 17:18:24,856 - ERROR - ERRO no processamento automático: Erro ao processar dados: sequence item 0: expected str instance, float found
Traceback (most recent call last):
  File "C:\Users\miqueias.silva\Documents\HADES\main.py", line 599, in process_excel_file
    .agg({
     ^^^^^
  File "c:\Users\miqueias.silva\AppData\Local\Programs\Python\Python312\Lib\site-packages\pandas\core\groupby\generic.py", line 1432, in aggregate
    result = op.agg()
             ^^^^^^^^
  File "c:\Users\miqueias.silva\AppData\Local\Programs\Python\Python312\Lib\site-packages\pandas\core\apply.py", line 190, in agg
    return self.agg_dict_like()
           ^^^^^^^^^^^^^^^^^^^^
  File "c:\Users\miqueias.silva\AppData\Local\Programs\Python\Python312\Lib\site-packages\pandas\core\apply.py", line 423, in agg_dict_like
    return self.agg_or_apply_dict_like(op_name="agg")
           ^^^^^^^^^^^^^^^^^^^^^^^^^^^^^^^^^^^^^^^^^^
  File "c:\Users\miqueias.silva\AppData\Local\Programs\Python\Python312\Lib\site-packages\pandas\core\apply.py", line 1608, in agg_or_apply_dict_like
    result_index, result_data = self.compute_dict_like(
                                ^^^^^^^^^^^^^^^^^^^^^^^
  File "c:\Users\miqueias.silva\AppData\Local\Programs\Python\Python312\Lib\site-packages\pandas\core\apply.py", line 497, in compute_dict_like
    getattr(obj._gotitem(key, ndim=1), op_name)(how, **kwargs)
  File "c:\Users\miqueias.silva\AppData\Local\Programs\Python\Python312\Lib\site-packages\pandas\core\groupby\generic.py", line 291, in aggregate
    return self._python_agg_general(func, *args, **kwargs)
           ^^^^^^^^^^^^^^^^^^^^^^^^^^^^^^^^^^^^^^^^^^^^^^^
  File "c:\Users\miqueias.silva\AppData\Local\Programs\Python\Python312\Lib\site-packages\pandas\core\groupby\generic.py", line 327, in _python_agg_general
    result = self._grouper.agg_series(obj, f)
             ^^^^^^^^^^^^^^^^^^^^^^^^^^^^^^^^
  File "c:\Users\miqueias.silva\AppData\Local\Programs\Python\Python312\Lib\site-packages\pandas\core\groupby\ops.py", line 864, in agg_series
    result = self._aggregate_series_pure_python(obj, func)
             ^^^^^^^^^^^^^^^^^^^^^^^^^^^^^^^^^^^^^^^^^^^^^
  File "c:\Users\miqueias.silva\AppData\Local\Programs\Python\Python312\Lib\site-packages\pandas\core\groupby\ops.py", line 885, in _aggregate_series_pure_python
    res = func(group)
          ^^^^^^^^^^^
  File "c:\Users\miqueias.silva\AppData\Local\Programs\Python\Python312\Lib\site-packages\pandas\core\groupby\generic.py", line 324, in <lambda>
    f = lambda x: func(x, *args, **kwargs)
                  ^^^^^^^^^^^^^^^^^^^^^^^^
  File "C:\Users\miqueias.silva\Documents\HADES\main.py", line 601, in <lambda>
    "OPERADOR": lambda x: "/".join(sorted(set(x)))
                          ^^^^^^^^^^^^^^^^^^^^^^^^
TypeError: sequence item 0: expected str instance, float found

During handling of the above exception, another exception occurred:

Traceback (most recent call last):
  File "C:\Users\miqueias.silva\Documents\HADES\main.py", line 533, in processor
    self.process_excel_file(file_path, inventory_name)
  File "C:\Users\miqueias.silva\Documents\HADES\main.py", line 613, in process_excel_file
    raise ValueError(f"Erro ao processar dados: {str(e)}")
ValueError: Erro ao processar dados: sequence item 0: expected str instance, float found

2025-03-25 17:18:24,879 - INFO - ERRO ao processar C:\Users\miqueias.silva\Desktop\a3 - Inserir Dados de Contagem\teste.xlsx: Erro ao processar dados: sequence item 0: expected str instance, float found
Traceback (most recent call last):
  File "C:\Users\miqueias.silva\Documents\HADES\main.py", line 599, in process_excel_file
    .agg({
     ^^^^^
  File "c:\Users\miqueias.silva\AppData\Local\Programs\Python\Python312\Lib\site-packages\pandas\core\groupby\generic.py", line 1432, in aggregate
    result = op.agg()
             ^^^^^^^^
  File "c:\Users\miqueias.silva\AppData\Local\Programs\Python\Python312\Lib\site-packages\pandas\core\apply.py", line 190, in agg
    return self.agg_dict_like()
           ^^^^^^^^^^^^^^^^^^^^
  File "c:\Users\miqueias.silva\AppData\Local\Programs\Python\Python312\Lib\site-packages\pandas\core\apply.py", line 423, in agg_dict_like
    return self.agg_or_apply_dict_like(op_name="agg")
           ^^^^^^^^^^^^^^^^^^^^^^^^^^^^^^^^^^^^^^^^^^
  File "c:\Users\miqueias.silva\AppData\Local\Programs\Python\Python312\Lib\site-packages\pandas\core\apply.py", line 1608, in agg_or_apply_dict_like
    result_index, result_data = self.compute_dict_like(
                                ^^^^^^^^^^^^^^^^^^^^^^^
  File "c:\Users\miqueias.silva\AppData\Local\Programs\Python\Python312\Lib\site-packages\pandas\core\apply.py", line 497, in compute_dict_like
    getattr(obj._gotitem(key, ndim=1), op_name)(how, **kwargs)
  File "c:\Users\miqueias.silva\AppData\Local\Programs\Python\Python312\Lib\site-packages\pandas\core\groupby\generic.py", line 291, in aggregate
    return self._python_agg_general(func, *args, **kwargs)
           ^^^^^^^^^^^^^^^^^^^^^^^^^^^^^^^^^^^^^^^^^^^^^^^
  File "c:\Users\miqueias.silva\AppData\Local\Programs\Python\Python312\Lib\site-packages\pandas\core\groupby\generic.py", line 327, in _python_agg_general
    result = self._grouper.agg_series(obj, f)
             ^^^^^^^^^^^^^^^^^^^^^^^^^^^^^^^^
  File "c:\Users\miqueias.silva\AppData\Local\Programs\Python\Python312\Lib\site-packages\pandas\core\groupby\ops.py", line 864, in agg_series
    result = self._aggregate_series_pure_python(obj, func)
             ^^^^^^^^^^^^^^^^^^^^^^^^^^^^^^^^^^^^^^^^^^^^^
  File "c:\Users\miqueias.silva\AppData\Local\Programs\Python\Python312\Lib\site-packages\pandas\core\groupby\ops.py", line 885, in _aggregate_series_pure_python
    res = func(group)
          ^^^^^^^^^^^
  File "c:\Users\miqueias.silva\AppData\Local\Programs\Python\Python312\Lib\site-packages\pandas\core\groupby\generic.py", line 324, in <lambda>
    f = lambda x: func(x, *args, **kwargs)
                  ^^^^^^^^^^^^^^^^^^^^^^^^
  File "C:\Users\miqueias.silva\Documents\HADES\main.py", line 601, in <lambda>
    "OPERADOR": lambda x: "/".join(sorted(set(x)))
                          ^^^^^^^^^^^^^^^^^^^^^^^^
TypeError: sequence item 0: expected str instance, float found

During handling of the above exception, another exception occurred:

Traceback (most recent call last):
  File "C:\Users\miqueias.silva\Documents\HADES\main.py", line 613, in process_excel_file
    raise ValueError(f"Erro ao processar dados: {str(e)}")
ValueError: Erro ao processar dados: sequence item 0: expected str instance, float found

2025-03-25 17:18:24,897 - INFO - 
=== ERRO NO PROCESSAMENTO AUTOMÁTICO ===
2025-03-25 17:18:24,906 - INFO - ERRO no processamento automático: Erro ao processar dados: sequence item 0: expected str instance, float found
Traceback (most recent call last):
  File "C:\Users\miqueias.silva\Documents\HADES\main.py", line 599, in process_excel_file
    .agg({
     ^^^^^
  File "c:\Users\miqueias.silva\AppData\Local\Programs\Python\Python312\Lib\site-packages\pandas\core\groupby\generic.py", line 1432, in aggregate
    result = op.agg()
             ^^^^^^^^
  File "c:\Users\miqueias.silva\AppData\Local\Programs\Python\Python312\Lib\site-packages\pandas\core\apply.py", line 190, in agg
    return self.agg_dict_like()
           ^^^^^^^^^^^^^^^^^^^^
  File "c:\Users\miqueias.silva\AppData\Local\Programs\Python\Python312\Lib\site-packages\pandas\core\apply.py", line 423, in agg_dict_like
    return self.agg_or_apply_dict_like(op_name="agg")
           ^^^^^^^^^^^^^^^^^^^^^^^^^^^^^^^^^^^^^^^^^^
  File "c:\Users\miqueias.silva\AppData\Local\Programs\Python\Python312\Lib\site-packages\pandas\core\apply.py", line 1608, in agg_or_apply_dict_like
    result_index, result_data = self.compute_dict_like(
                                ^^^^^^^^^^^^^^^^^^^^^^^
  File "c:\Users\miqueias.silva\AppData\Local\Programs\Python\Python312\Lib\site-packages\pandas\core\apply.py", line 497, in compute_dict_like
    getattr(obj._gotitem(key, ndim=1), op_name)(how, **kwargs)
  File "c:\Users\miqueias.silva\AppData\Local\Programs\Python\Python312\Lib\site-packages\pandas\core\groupby\generic.py", line 291, in aggregate
    return self._python_agg_general(func, *args, **kwargs)
           ^^^^^^^^^^^^^^^^^^^^^^^^^^^^^^^^^^^^^^^^^^^^^^^
  File "c:\Users\miqueias.silva\AppData\Local\Programs\Python\Python312\Lib\site-packages\pandas\core\groupby\generic.py", line 327, in _python_agg_general
    result = self._grouper.agg_series(obj, f)
             ^^^^^^^^^^^^^^^^^^^^^^^^^^^^^^^^
  File "c:\Users\miqueias.silva\AppData\Local\Programs\Python\Python312\Lib\site-packages\pandas\core\groupby\ops.py", line 864, in agg_series
    result = self._aggregate_series_pure_python(obj, func)
             ^^^^^^^^^^^^^^^^^^^^^^^^^^^^^^^^^^^^^^^^^^^^^
  File "c:\Users\miqueias.silva\AppData\Local\Programs\Python\Python312\Lib\site-packages\pandas\core\groupby\ops.py", line 885, in _aggregate_series_pure_python
    res = func(group)
          ^^^^^^^^^^^
  File "c:\Users\miqueias.silva\AppData\Local\Programs\Python\Python312\Lib\site-packages\pandas\core\groupby\generic.py", line 324, in <lambda>
    f = lambda x: func(x, *args, **kwargs)
                  ^^^^^^^^^^^^^^^^^^^^^^^^
  File "C:\Users\miqueias.silva\Documents\HADES\main.py", line 601, in <lambda>
    "OPERADOR": lambda x: "/".join(sorted(set(x)))
                          ^^^^^^^^^^^^^^^^^^^^^^^^
TypeError: sequence item 0: expected str instance, float found

During handling of the above exception, another exception occurred:

Traceback (most recent call last):
  File "C:\Users\miqueias.silva\Documents\HADES\main.py", line 533, in processor
    self.process_excel_file(file_path, inventory_name)
  File "C:\Users\miqueias.silva\Documents\HADES\main.py", line 613, in process_excel_file
    raise ValueError(f"Erro ao processar dados: {str(e)}")
ValueError: Erro ao processar dados: sequence item 0: expected str instance, float found

2025-03-25 17:18:27,685 - INFO - Arquivo CSV salvo em: Inventário\a3\dados_processados\output.csv
2025-03-25 17:22:48,066 - INFO - Inventários disponíveis: a1, a2, a3
2025-03-25 17:23:02,669 - INFO - 
=== INICIANDO CRIAÇÃO DE INVENTÁRIO ===
2025-03-25 17:23:02,669 - INFO - Nome: a5
2025-03-25 17:23:02,669 - INFO - Loja: a5
2025-03-25 17:23:02,669 - INFO - Responsável: a5
2025-03-25 17:23:02,669 - INFO - Estrutura criada com sucesso em: Inventário\a5
2025-03-25 17:23:02,669 - INFO - Pasta de contagem criada na área de trabalho: C:\Users\miqueias.silva\Desktop\a5 - Inserir Dados de Contagem
2025-03-25 17:23:02,681 - INFO - Monitoramento iniciado para: C:\Users\miqueias.silva\Desktop\a5 - Inserir Dados de Contagem
2025-03-25 17:23:02,685 - INFO - 
=== MONITORAMENTO INICIADO ===
2025-03-25 17:23:02,688 - INFO - Data/Hora: 25/03/2025 17:23:02
2025-03-25 17:23:02,691 - INFO - Pasta: C:\Users\miqueias.silva\Desktop\a5 - Inserir Dados de Contagem
2025-03-25 17:23:02,694 - INFO - Inventário: a5
2025-03-25 17:23:03,833 - INFO - Inventários disponíveis: a5
2025-03-25 17:23:10,408 - INFO - Arquivo selecionado: C:/Users/miqueias.silva/Desktop/Invent (3).txt
2025-03-25 17:23:10,755 - INFO - 
=== INICIANDO PROCESSAMENTO ===
2025-03-25 17:23:10,757 - INFO - Arquivo: C:/Users/miqueias.silva/Desktop/Invent (3).txt
2025-03-25 17:23:10,757 - INFO - Destino: a5
2025-03-25 17:23:10,757 - INFO - Data/Hora: 25/03/2025 17:23:10
2025-03-25 17:23:19,711 - INFO - Arquivo CSV salvo em: Inventário\a5\dados_processados\output.csv
2025-03-25 17:23:28,115 - INFO - === PROCESSAMENTO CONCLUÍDO ===
2025-03-25 17:23:28,115 - INFO - Tempo total: 8.95 segundos
2025-03-25 17:23:28,115 - INFO - Registros processados: 1106652
2025-03-25 17:23:28,115 - INFO - Arquivo gerado: Inventário\a5\dados_processados\output.csv
2025-03-25 17:23:33,932 - INFO - Novo arquivo detectado: C:\Users\miqueias.silva\Desktop\a5 - Inserir Dados de Contagem\teste_parte_2.xlsx
2025-03-25 17:23:33,933 - INFO - Iniciando processamento do arquivo: C:\Users\miqueias.silva\Desktop\a5 - Inserir Dados de Contagem\teste_parte_2.xlsx
2025-03-25 17:23:33,944 - INFO - 
=== INICIANDO PROCESSAMENTO ===
2025-03-25 17:23:33,947 - INFO - Arquivo: C:\Users\miqueias.silva\Desktop\a5 - Inserir Dados de Contagem\teste_parte_2.xlsx
2025-03-25 17:23:33,965 - INFO - Inventário: a5
2025-03-25 17:23:33,968 - INFO - Data/Hora: 25/03/2025 17:23:33
2025-03-25 17:23:33,969 - INFO - 
Novo arquivo detectado e adicionado à fila: C:\Users\miqueias.silva\Desktop\a5 - Inserir Dados de Contagem\teste_parte_2.xlsx
2025-03-25 17:23:33,969 - INFO - Novo arquivo detectado: C:\Users\miqueias.silva\Desktop\a5 - Inserir Dados de Contagem\teste_parte_1.xlsx
2025-03-25 17:23:33,989 - INFO - 
Novo arquivo detectado e adicionado à fila: C:\Users\miqueias.silva\Desktop\a5 - Inserir Dados de Contagem\teste_parte_1.xlsx
2025-03-25 17:23:34,548 - INFO - Arquivo Excel lido com sucesso
2025-03-25 17:23:34,553 - ERROR - ERRO ao processar C:\Users\miqueias.silva\Desktop\a5 - Inserir Dados de Contagem\teste_parte_2.xlsx: Erro ao processar dados: sequence item 0: expected str instance, float found
Traceback (most recent call last):
  File "C:\Users\miqueias.silva\Documents\HADES\main.py", line 599, in process_excel_file
    .agg({
     ^^^^^
  File "c:\Users\miqueias.silva\AppData\Local\Programs\Python\Python312\Lib\site-packages\pandas\core\groupby\generic.py", line 1432, in aggregate
    result = op.agg()
             ^^^^^^^^
  File "c:\Users\miqueias.silva\AppData\Local\Programs\Python\Python312\Lib\site-packages\pandas\core\apply.py", line 190, in agg
    return self.agg_dict_like()
           ^^^^^^^^^^^^^^^^^^^^
  File "c:\Users\miqueias.silva\AppData\Local\Programs\Python\Python312\Lib\site-packages\pandas\core\apply.py", line 423, in agg_dict_like
    return self.agg_or_apply_dict_like(op_name="agg")
           ^^^^^^^^^^^^^^^^^^^^^^^^^^^^^^^^^^^^^^^^^^
  File "c:\Users\miqueias.silva\AppData\Local\Programs\Python\Python312\Lib\site-packages\pandas\core\apply.py", line 1608, in agg_or_apply_dict_like
    result_index, result_data = self.compute_dict_like(
                                ^^^^^^^^^^^^^^^^^^^^^^^
  File "c:\Users\miqueias.silva\AppData\Local\Programs\Python\Python312\Lib\site-packages\pandas\core\apply.py", line 497, in compute_dict_like
    getattr(obj._gotitem(key, ndim=1), op_name)(how, **kwargs)
  File "c:\Users\miqueias.silva\AppData\Local\Programs\Python\Python312\Lib\site-packages\pandas\core\groupby\generic.py", line 291, in aggregate
    return self._python_agg_general(func, *args, **kwargs)
           ^^^^^^^^^^^^^^^^^^^^^^^^^^^^^^^^^^^^^^^^^^^^^^^
  File "c:\Users\miqueias.silva\AppData\Local\Programs\Python\Python312\Lib\site-packages\pandas\core\groupby\generic.py", line 327, in _python_agg_general
    result = self._grouper.agg_series(obj, f)
             ^^^^^^^^^^^^^^^^^^^^^^^^^^^^^^^^
  File "c:\Users\miqueias.silva\AppData\Local\Programs\Python\Python312\Lib\site-packages\pandas\core\groupby\ops.py", line 864, in agg_series
    result = self._aggregate_series_pure_python(obj, func)
             ^^^^^^^^^^^^^^^^^^^^^^^^^^^^^^^^^^^^^^^^^^^^^
  File "c:\Users\miqueias.silva\AppData\Local\Programs\Python\Python312\Lib\site-packages\pandas\core\groupby\ops.py", line 885, in _aggregate_series_pure_python
    res = func(group)
          ^^^^^^^^^^^
  File "c:\Users\miqueias.silva\AppData\Local\Programs\Python\Python312\Lib\site-packages\pandas\core\groupby\generic.py", line 324, in <lambda>
    f = lambda x: func(x, *args, **kwargs)
                  ^^^^^^^^^^^^^^^^^^^^^^^^
  File "C:\Users\miqueias.silva\Documents\HADES\main.py", line 601, in <lambda>
    "OPERADOR": lambda x: "/".join(sorted(set(x)))
                          ^^^^^^^^^^^^^^^^^^^^^^^^
TypeError: sequence item 0: expected str instance, float found

During handling of the above exception, another exception occurred:

Traceback (most recent call last):
  File "C:\Users\miqueias.silva\Documents\HADES\main.py", line 613, in process_excel_file
    raise ValueError(f"Erro ao processar dados: {str(e)}")
ValueError: Erro ao processar dados: sequence item 0: expected str instance, float found

2025-03-25 17:23:34,562 - ERROR - ERRO no processamento automático: Erro ao processar dados: sequence item 0: expected str instance, float found
Traceback (most recent call last):
  File "C:\Users\miqueias.silva\Documents\HADES\main.py", line 599, in process_excel_file
    .agg({
     ^^^^^
  File "c:\Users\miqueias.silva\AppData\Local\Programs\Python\Python312\Lib\site-packages\pandas\core\groupby\generic.py", line 1432, in aggregate
    result = op.agg()
             ^^^^^^^^
  File "c:\Users\miqueias.silva\AppData\Local\Programs\Python\Python312\Lib\site-packages\pandas\core\apply.py", line 190, in agg
    return self.agg_dict_like()
           ^^^^^^^^^^^^^^^^^^^^
  File "c:\Users\miqueias.silva\AppData\Local\Programs\Python\Python312\Lib\site-packages\pandas\core\apply.py", line 423, in agg_dict_like
    return self.agg_or_apply_dict_like(op_name="agg")
           ^^^^^^^^^^^^^^^^^^^^^^^^^^^^^^^^^^^^^^^^^^
  File "c:\Users\miqueias.silva\AppData\Local\Programs\Python\Python312\Lib\site-packages\pandas\core\apply.py", line 1608, in agg_or_apply_dict_like
    result_index, result_data = self.compute_dict_like(
                                ^^^^^^^^^^^^^^^^^^^^^^^
  File "c:\Users\miqueias.silva\AppData\Local\Programs\Python\Python312\Lib\site-packages\pandas\core\apply.py", line 497, in compute_dict_like
    getattr(obj._gotitem(key, ndim=1), op_name)(how, **kwargs)
  File "c:\Users\miqueias.silva\AppData\Local\Programs\Python\Python312\Lib\site-packages\pandas\core\groupby\generic.py", line 291, in aggregate
    return self._python_agg_general(func, *args, **kwargs)
           ^^^^^^^^^^^^^^^^^^^^^^^^^^^^^^^^^^^^^^^^^^^^^^^
  File "c:\Users\miqueias.silva\AppData\Local\Programs\Python\Python312\Lib\site-packages\pandas\core\groupby\generic.py", line 327, in _python_agg_general
    result = self._grouper.agg_series(obj, f)
             ^^^^^^^^^^^^^^^^^^^^^^^^^^^^^^^^
  File "c:\Users\miqueias.silva\AppData\Local\Programs\Python\Python312\Lib\site-packages\pandas\core\groupby\ops.py", line 864, in agg_series
    result = self._aggregate_series_pure_python(obj, func)
             ^^^^^^^^^^^^^^^^^^^^^^^^^^^^^^^^^^^^^^^^^^^^^
  File "c:\Users\miqueias.silva\AppData\Local\Programs\Python\Python312\Lib\site-packages\pandas\core\groupby\ops.py", line 885, in _aggregate_series_pure_python
    res = func(group)
          ^^^^^^^^^^^
  File "c:\Users\miqueias.silva\AppData\Local\Programs\Python\Python312\Lib\site-packages\pandas\core\groupby\generic.py", line 324, in <lambda>
    f = lambda x: func(x, *args, **kwargs)
                  ^^^^^^^^^^^^^^^^^^^^^^^^
  File "C:\Users\miqueias.silva\Documents\HADES\main.py", line 601, in <lambda>
    "OPERADOR": lambda x: "/".join(sorted(set(x)))
                          ^^^^^^^^^^^^^^^^^^^^^^^^
TypeError: sequence item 0: expected str instance, float found

During handling of the above exception, another exception occurred:

Traceback (most recent call last):
  File "C:\Users\miqueias.silva\Documents\HADES\main.py", line 533, in processor
    self.process_excel_file(file_path, inventory_name)
  File "C:\Users\miqueias.silva\Documents\HADES\main.py", line 613, in process_excel_file
    raise ValueError(f"Erro ao processar dados: {str(e)}")
ValueError: Erro ao processar dados: sequence item 0: expected str instance, float found

2025-03-25 17:23:34,562 - INFO - === ERRO NO PROCESSAMENTO ===
2025-03-25 17:23:34,567 - INFO - ERRO ao processar C:\Users\miqueias.silva\Desktop\a5 - Inserir Dados de Contagem\teste_parte_2.xlsx: Erro ao processar dados: sequence item 0: expected str instance, float found
Traceback (most recent call last):
  File "C:\Users\miqueias.silva\Documents\HADES\main.py", line 599, in process_excel_file
    .agg({
     ^^^^^
  File "c:\Users\miqueias.silva\AppData\Local\Programs\Python\Python312\Lib\site-packages\pandas\core\groupby\generic.py", line 1432, in aggregate
    result = op.agg()
             ^^^^^^^^
  File "c:\Users\miqueias.silva\AppData\Local\Programs\Python\Python312\Lib\site-packages\pandas\core\apply.py", line 190, in agg
    return self.agg_dict_like()
           ^^^^^^^^^^^^^^^^^^^^
  File "c:\Users\miqueias.silva\AppData\Local\Programs\Python\Python312\Lib\site-packages\pandas\core\apply.py", line 423, in agg_dict_like
    return self.agg_or_apply_dict_like(op_name="agg")
           ^^^^^^^^^^^^^^^^^^^^^^^^^^^^^^^^^^^^^^^^^^
  File "c:\Users\miqueias.silva\AppData\Local\Programs\Python\Python312\Lib\site-packages\pandas\core\apply.py", line 1608, in agg_or_apply_dict_like
    result_index, result_data = self.compute_dict_like(
                                ^^^^^^^^^^^^^^^^^^^^^^^
  File "c:\Users\miqueias.silva\AppData\Local\Programs\Python\Python312\Lib\site-packages\pandas\core\apply.py", line 497, in compute_dict_like
    getattr(obj._gotitem(key, ndim=1), op_name)(how, **kwargs)
  File "c:\Users\miqueias.silva\AppData\Local\Programs\Python\Python312\Lib\site-packages\pandas\core\groupby\generic.py", line 291, in aggregate
    return self._python_agg_general(func, *args, **kwargs)
           ^^^^^^^^^^^^^^^^^^^^^^^^^^^^^^^^^^^^^^^^^^^^^^^
  File "c:\Users\miqueias.silva\AppData\Local\Programs\Python\Python312\Lib\site-packages\pandas\core\groupby\generic.py", line 327, in _python_agg_general
    result = self._grouper.agg_series(obj, f)
             ^^^^^^^^^^^^^^^^^^^^^^^^^^^^^^^^
  File "c:\Users\miqueias.silva\AppData\Local\Programs\Python\Python312\Lib\site-packages\pandas\core\groupby\ops.py", line 864, in agg_series
    result = self._aggregate_series_pure_python(obj, func)
             ^^^^^^^^^^^^^^^^^^^^^^^^^^^^^^^^^^^^^^^^^^^^^
  File "c:\Users\miqueias.silva\AppData\Local\Programs\Python\Python312\Lib\site-packages\pandas\core\groupby\ops.py", line 885, in _aggregate_series_pure_python
    res = func(group)
          ^^^^^^^^^^^
  File "c:\Users\miqueias.silva\AppData\Local\Programs\Python\Python312\Lib\site-packages\pandas\core\groupby\generic.py", line 324, in <lambda>
    f = lambda x: func(x, *args, **kwargs)
                  ^^^^^^^^^^^^^^^^^^^^^^^^
  File "C:\Users\miqueias.silva\Documents\HADES\main.py", line 601, in <lambda>
    "OPERADOR": lambda x: "/".join(sorted(set(x)))
                          ^^^^^^^^^^^^^^^^^^^^^^^^
TypeError: sequence item 0: expected str instance, float found

During handling of the above exception, another exception occurred:

Traceback (most recent call last):
  File "C:\Users\miqueias.silva\Documents\HADES\main.py", line 613, in process_excel_file
    raise ValueError(f"Erro ao processar dados: {str(e)}")
ValueError: Erro ao processar dados: sequence item 0: expected str instance, float found

2025-03-25 17:23:34,571 - INFO - 
=== ERRO NO PROCESSAMENTO AUTOMÁTICO ===
2025-03-25 17:23:34,573 - INFO - ERRO no processamento automático: Erro ao processar dados: sequence item 0: expected str instance, float found
Traceback (most recent call last):
  File "C:\Users\miqueias.silva\Documents\HADES\main.py", line 599, in process_excel_file
    .agg({
     ^^^^^
  File "c:\Users\miqueias.silva\AppData\Local\Programs\Python\Python312\Lib\site-packages\pandas\core\groupby\generic.py", line 1432, in aggregate
    result = op.agg()
             ^^^^^^^^
  File "c:\Users\miqueias.silva\AppData\Local\Programs\Python\Python312\Lib\site-packages\pandas\core\apply.py", line 190, in agg
    return self.agg_dict_like()
           ^^^^^^^^^^^^^^^^^^^^
  File "c:\Users\miqueias.silva\AppData\Local\Programs\Python\Python312\Lib\site-packages\pandas\core\apply.py", line 423, in agg_dict_like
    return self.agg_or_apply_dict_like(op_name="agg")
           ^^^^^^^^^^^^^^^^^^^^^^^^^^^^^^^^^^^^^^^^^^
  File "c:\Users\miqueias.silva\AppData\Local\Programs\Python\Python312\Lib\site-packages\pandas\core\apply.py", line 1608, in agg_or_apply_dict_like
    result_index, result_data = self.compute_dict_like(
                                ^^^^^^^^^^^^^^^^^^^^^^^
  File "c:\Users\miqueias.silva\AppData\Local\Programs\Python\Python312\Lib\site-packages\pandas\core\apply.py", line 497, in compute_dict_like
    getattr(obj._gotitem(key, ndim=1), op_name)(how, **kwargs)
  File "c:\Users\miqueias.silva\AppData\Local\Programs\Python\Python312\Lib\site-packages\pandas\core\groupby\generic.py", line 291, in aggregate
    return self._python_agg_general(func, *args, **kwargs)
           ^^^^^^^^^^^^^^^^^^^^^^^^^^^^^^^^^^^^^^^^^^^^^^^
  File "c:\Users\miqueias.silva\AppData\Local\Programs\Python\Python312\Lib\site-packages\pandas\core\groupby\generic.py", line 327, in _python_agg_general
    result = self._grouper.agg_series(obj, f)
             ^^^^^^^^^^^^^^^^^^^^^^^^^^^^^^^^
  File "c:\Users\miqueias.silva\AppData\Local\Programs\Python\Python312\Lib\site-packages\pandas\core\groupby\ops.py", line 864, in agg_series
    result = self._aggregate_series_pure_python(obj, func)
             ^^^^^^^^^^^^^^^^^^^^^^^^^^^^^^^^^^^^^^^^^^^^^
  File "c:\Users\miqueias.silva\AppData\Local\Programs\Python\Python312\Lib\site-packages\pandas\core\groupby\ops.py", line 885, in _aggregate_series_pure_python
    res = func(group)
          ^^^^^^^^^^^
  File "c:\Users\miqueias.silva\AppData\Local\Programs\Python\Python312\Lib\site-packages\pandas\core\groupby\generic.py", line 324, in <lambda>
    f = lambda x: func(x, *args, **kwargs)
                  ^^^^^^^^^^^^^^^^^^^^^^^^
  File "C:\Users\miqueias.silva\Documents\HADES\main.py", line 601, in <lambda>
    "OPERADOR": lambda x: "/".join(sorted(set(x)))
                          ^^^^^^^^^^^^^^^^^^^^^^^^
TypeError: sequence item 0: expected str instance, float found

During handling of the above exception, another exception occurred:

Traceback (most recent call last):
  File "C:\Users\miqueias.silva\Documents\HADES\main.py", line 533, in processor
    self.process_excel_file(file_path, inventory_name)
  File "C:\Users\miqueias.silva\Documents\HADES\main.py", line 613, in process_excel_file
    raise ValueError(f"Erro ao processar dados: {str(e)}")
ValueError: Erro ao processar dados: sequence item 0: expected str instance, float found

2025-03-25 17:23:34,573 - INFO - Iniciando processamento do arquivo: C:\Users\miqueias.silva\Desktop\a5 - Inserir Dados de Contagem\teste_parte_1.xlsx
2025-03-25 17:23:34,581 - INFO - 
=== INICIANDO PROCESSAMENTO ===
2025-03-25 17:23:34,587 - INFO - Arquivo: C:\Users\miqueias.silva\Desktop\a5 - Inserir Dados de Contagem\teste_parte_1.xlsx
2025-03-25 17:23:34,595 - INFO - Inventário: a5
2025-03-25 17:23:34,620 - INFO - Data/Hora: 25/03/2025 17:23:34
2025-03-25 17:23:34,710 - INFO - Arquivo Excel lido com sucesso
2025-03-25 17:23:34,713 - ERROR - ERRO ao processar C:\Users\miqueias.silva\Desktop\a5 - Inserir Dados de Contagem\teste_parte_1.xlsx: Erro ao processar dados: sequence item 0: expected str instance, float found
Traceback (most recent call last):
  File "C:\Users\miqueias.silva\Documents\HADES\main.py", line 599, in process_excel_file
    .agg({
     ^^^^^
  File "c:\Users\miqueias.silva\AppData\Local\Programs\Python\Python312\Lib\site-packages\pandas\core\groupby\generic.py", line 1432, in aggregate
    result = op.agg()
             ^^^^^^^^
  File "c:\Users\miqueias.silva\AppData\Local\Programs\Python\Python312\Lib\site-packages\pandas\core\apply.py", line 190, in agg
    return self.agg_dict_like()
           ^^^^^^^^^^^^^^^^^^^^
  File "c:\Users\miqueias.silva\AppData\Local\Programs\Python\Python312\Lib\site-packages\pandas\core\apply.py", line 423, in agg_dict_like
    return self.agg_or_apply_dict_like(op_name="agg")
           ^^^^^^^^^^^^^^^^^^^^^^^^^^^^^^^^^^^^^^^^^^
  File "c:\Users\miqueias.silva\AppData\Local\Programs\Python\Python312\Lib\site-packages\pandas\core\apply.py", line 1608, in agg_or_apply_dict_like
    result_index, result_data = self.compute_dict_like(
                                ^^^^^^^^^^^^^^^^^^^^^^^
  File "c:\Users\miqueias.silva\AppData\Local\Programs\Python\Python312\Lib\site-packages\pandas\core\apply.py", line 497, in compute_dict_like
    getattr(obj._gotitem(key, ndim=1), op_name)(how, **kwargs)
  File "c:\Users\miqueias.silva\AppData\Local\Programs\Python\Python312\Lib\site-packages\pandas\core\groupby\generic.py", line 291, in aggregate
    return self._python_agg_general(func, *args, **kwargs)
           ^^^^^^^^^^^^^^^^^^^^^^^^^^^^^^^^^^^^^^^^^^^^^^^
  File "c:\Users\miqueias.silva\AppData\Local\Programs\Python\Python312\Lib\site-packages\pandas\core\groupby\generic.py", line 327, in _python_agg_general
    result = self._grouper.agg_series(obj, f)
             ^^^^^^^^^^^^^^^^^^^^^^^^^^^^^^^^
  File "c:\Users\miqueias.silva\AppData\Local\Programs\Python\Python312\Lib\site-packages\pandas\core\groupby\ops.py", line 864, in agg_series
    result = self._aggregate_series_pure_python(obj, func)
             ^^^^^^^^^^^^^^^^^^^^^^^^^^^^^^^^^^^^^^^^^^^^^
  File "c:\Users\miqueias.silva\AppData\Local\Programs\Python\Python312\Lib\site-packages\pandas\core\groupby\ops.py", line 885, in _aggregate_series_pure_python
    res = func(group)
          ^^^^^^^^^^^
  File "c:\Users\miqueias.silva\AppData\Local\Programs\Python\Python312\Lib\site-packages\pandas\core\groupby\generic.py", line 324, in <lambda>
    f = lambda x: func(x, *args, **kwargs)
                  ^^^^^^^^^^^^^^^^^^^^^^^^
  File "C:\Users\miqueias.silva\Documents\HADES\main.py", line 601, in <lambda>
    "OPERADOR": lambda x: "/".join(sorted(set(x)))
                          ^^^^^^^^^^^^^^^^^^^^^^^^
TypeError: sequence item 0: expected str instance, float found

During handling of the above exception, another exception occurred:

Traceback (most recent call last):
  File "C:\Users\miqueias.silva\Documents\HADES\main.py", line 613, in process_excel_file
    raise ValueError(f"Erro ao processar dados: {str(e)}")
ValueError: Erro ao processar dados: sequence item 0: expected str instance, float found

2025-03-25 17:23:34,715 - ERROR - ERRO no processamento automático: Erro ao processar dados: sequence item 0: expected str instance, float found
Traceback (most recent call last):
  File "C:\Users\miqueias.silva\Documents\HADES\main.py", line 599, in process_excel_file
    .agg({
     ^^^^^
  File "c:\Users\miqueias.silva\AppData\Local\Programs\Python\Python312\Lib\site-packages\pandas\core\groupby\generic.py", line 1432, in aggregate
    result = op.agg()
             ^^^^^^^^
  File "c:\Users\miqueias.silva\AppData\Local\Programs\Python\Python312\Lib\site-packages\pandas\core\apply.py", line 190, in agg
    return self.agg_dict_like()
           ^^^^^^^^^^^^^^^^^^^^
  File "c:\Users\miqueias.silva\AppData\Local\Programs\Python\Python312\Lib\site-packages\pandas\core\apply.py", line 423, in agg_dict_like
    return self.agg_or_apply_dict_like(op_name="agg")
           ^^^^^^^^^^^^^^^^^^^^^^^^^^^^^^^^^^^^^^^^^^
  File "c:\Users\miqueias.silva\AppData\Local\Programs\Python\Python312\Lib\site-packages\pandas\core\apply.py", line 1608, in agg_or_apply_dict_like
    result_index, result_data = self.compute_dict_like(
                                ^^^^^^^^^^^^^^^^^^^^^^^
  File "c:\Users\miqueias.silva\AppData\Local\Programs\Python\Python312\Lib\site-packages\pandas\core\apply.py", line 497, in compute_dict_like
    getattr(obj._gotitem(key, ndim=1), op_name)(how, **kwargs)
  File "c:\Users\miqueias.silva\AppData\Local\Programs\Python\Python312\Lib\site-packages\pandas\core\groupby\generic.py", line 291, in aggregate
    return self._python_agg_general(func, *args, **kwargs)
           ^^^^^^^^^^^^^^^^^^^^^^^^^^^^^^^^^^^^^^^^^^^^^^^
  File "c:\Users\miqueias.silva\AppData\Local\Programs\Python\Python312\Lib\site-packages\pandas\core\groupby\generic.py", line 327, in _python_agg_general
    result = self._grouper.agg_series(obj, f)
             ^^^^^^^^^^^^^^^^^^^^^^^^^^^^^^^^
  File "c:\Users\miqueias.silva\AppData\Local\Programs\Python\Python312\Lib\site-packages\pandas\core\groupby\ops.py", line 864, in agg_series
    result = self._aggregate_series_pure_python(obj, func)
             ^^^^^^^^^^^^^^^^^^^^^^^^^^^^^^^^^^^^^^^^^^^^^
  File "c:\Users\miqueias.silva\AppData\Local\Programs\Python\Python312\Lib\site-packages\pandas\core\groupby\ops.py", line 885, in _aggregate_series_pure_python
    res = func(group)
          ^^^^^^^^^^^
  File "c:\Users\miqueias.silva\AppData\Local\Programs\Python\Python312\Lib\site-packages\pandas\core\groupby\generic.py", line 324, in <lambda>
    f = lambda x: func(x, *args, **kwargs)
                  ^^^^^^^^^^^^^^^^^^^^^^^^
  File "C:\Users\miqueias.silva\Documents\HADES\main.py", line 601, in <lambda>
    "OPERADOR": lambda x: "/".join(sorted(set(x)))
                          ^^^^^^^^^^^^^^^^^^^^^^^^
TypeError: sequence item 0: expected str instance, float found

During handling of the above exception, another exception occurred:

Traceback (most recent call last):
  File "C:\Users\miqueias.silva\Documents\HADES\main.py", line 533, in processor
    self.process_excel_file(file_path, inventory_name)
  File "C:\Users\miqueias.silva\Documents\HADES\main.py", line 613, in process_excel_file
    raise ValueError(f"Erro ao processar dados: {str(e)}")
ValueError: Erro ao processar dados: sequence item 0: expected str instance, float found

2025-03-25 17:23:34,716 - INFO - === ERRO NO PROCESSAMENTO ===
2025-03-25 17:23:34,720 - INFO - ERRO ao processar C:\Users\miqueias.silva\Desktop\a5 - Inserir Dados de Contagem\teste_parte_1.xlsx: Erro ao processar dados: sequence item 0: expected str instance, float found
Traceback (most recent call last):
  File "C:\Users\miqueias.silva\Documents\HADES\main.py", line 599, in process_excel_file
    .agg({
     ^^^^^
  File "c:\Users\miqueias.silva\AppData\Local\Programs\Python\Python312\Lib\site-packages\pandas\core\groupby\generic.py", line 1432, in aggregate
    result = op.agg()
             ^^^^^^^^
  File "c:\Users\miqueias.silva\AppData\Local\Programs\Python\Python312\Lib\site-packages\pandas\core\apply.py", line 190, in agg
    return self.agg_dict_like()
           ^^^^^^^^^^^^^^^^^^^^
  File "c:\Users\miqueias.silva\AppData\Local\Programs\Python\Python312\Lib\site-packages\pandas\core\apply.py", line 423, in agg_dict_like
    return self.agg_or_apply_dict_like(op_name="agg")
           ^^^^^^^^^^^^^^^^^^^^^^^^^^^^^^^^^^^^^^^^^^
  File "c:\Users\miqueias.silva\AppData\Local\Programs\Python\Python312\Lib\site-packages\pandas\core\apply.py", line 1608, in agg_or_apply_dict_like
    result_index, result_data = self.compute_dict_like(
                                ^^^^^^^^^^^^^^^^^^^^^^^
  File "c:\Users\miqueias.silva\AppData\Local\Programs\Python\Python312\Lib\site-packages\pandas\core\apply.py", line 497, in compute_dict_like
    getattr(obj._gotitem(key, ndim=1), op_name)(how, **kwargs)
  File "c:\Users\miqueias.silva\AppData\Local\Programs\Python\Python312\Lib\site-packages\pandas\core\groupby\generic.py", line 291, in aggregate
    return self._python_agg_general(func, *args, **kwargs)
           ^^^^^^^^^^^^^^^^^^^^^^^^^^^^^^^^^^^^^^^^^^^^^^^
  File "c:\Users\miqueias.silva\AppData\Local\Programs\Python\Python312\Lib\site-packages\pandas\core\groupby\generic.py", line 327, in _python_agg_general
    result = self._grouper.agg_series(obj, f)
             ^^^^^^^^^^^^^^^^^^^^^^^^^^^^^^^^
  File "c:\Users\miqueias.silva\AppData\Local\Programs\Python\Python312\Lib\site-packages\pandas\core\groupby\ops.py", line 864, in agg_series
    result = self._aggregate_series_pure_python(obj, func)
             ^^^^^^^^^^^^^^^^^^^^^^^^^^^^^^^^^^^^^^^^^^^^^
  File "c:\Users\miqueias.silva\AppData\Local\Programs\Python\Python312\Lib\site-packages\pandas\core\groupby\ops.py", line 885, in _aggregate_series_pure_python
    res = func(group)
          ^^^^^^^^^^^
  File "c:\Users\miqueias.silva\AppData\Local\Programs\Python\Python312\Lib\site-packages\pandas\core\groupby\generic.py", line 324, in <lambda>
    f = lambda x: func(x, *args, **kwargs)
                  ^^^^^^^^^^^^^^^^^^^^^^^^
  File "C:\Users\miqueias.silva\Documents\HADES\main.py", line 601, in <lambda>
    "OPERADOR": lambda x: "/".join(sorted(set(x)))
                          ^^^^^^^^^^^^^^^^^^^^^^^^
TypeError: sequence item 0: expected str instance, float found

During handling of the above exception, another exception occurred:

Traceback (most recent call last):
  File "C:\Users\miqueias.silva\Documents\HADES\main.py", line 613, in process_excel_file
    raise ValueError(f"Erro ao processar dados: {str(e)}")
ValueError: Erro ao processar dados: sequence item 0: expected str instance, float found

2025-03-25 17:23:34,725 - INFO - 
=== ERRO NO PROCESSAMENTO AUTOMÁTICO ===
2025-03-25 17:23:34,728 - INFO - ERRO no processamento automático: Erro ao processar dados: sequence item 0: expected str instance, float found
Traceback (most recent call last):
  File "C:\Users\miqueias.silva\Documents\HADES\main.py", line 599, in process_excel_file
    .agg({
     ^^^^^
  File "c:\Users\miqueias.silva\AppData\Local\Programs\Python\Python312\Lib\site-packages\pandas\core\groupby\generic.py", line 1432, in aggregate
    result = op.agg()
             ^^^^^^^^
  File "c:\Users\miqueias.silva\AppData\Local\Programs\Python\Python312\Lib\site-packages\pandas\core\apply.py", line 190, in agg
    return self.agg_dict_like()
           ^^^^^^^^^^^^^^^^^^^^
  File "c:\Users\miqueias.silva\AppData\Local\Programs\Python\Python312\Lib\site-packages\pandas\core\apply.py", line 423, in agg_dict_like
    return self.agg_or_apply_dict_like(op_name="agg")
           ^^^^^^^^^^^^^^^^^^^^^^^^^^^^^^^^^^^^^^^^^^
  File "c:\Users\miqueias.silva\AppData\Local\Programs\Python\Python312\Lib\site-packages\pandas\core\apply.py", line 1608, in agg_or_apply_dict_like
    result_index, result_data = self.compute_dict_like(
                                ^^^^^^^^^^^^^^^^^^^^^^^
  File "c:\Users\miqueias.silva\AppData\Local\Programs\Python\Python312\Lib\site-packages\pandas\core\apply.py", line 497, in compute_dict_like
    getattr(obj._gotitem(key, ndim=1), op_name)(how, **kwargs)
  File "c:\Users\miqueias.silva\AppData\Local\Programs\Python\Python312\Lib\site-packages\pandas\core\groupby\generic.py", line 291, in aggregate
    return self._python_agg_general(func, *args, **kwargs)
           ^^^^^^^^^^^^^^^^^^^^^^^^^^^^^^^^^^^^^^^^^^^^^^^
  File "c:\Users\miqueias.silva\AppData\Local\Programs\Python\Python312\Lib\site-packages\pandas\core\groupby\generic.py", line 327, in _python_agg_general
    result = self._grouper.agg_series(obj, f)
             ^^^^^^^^^^^^^^^^^^^^^^^^^^^^^^^^
  File "c:\Users\miqueias.silva\AppData\Local\Programs\Python\Python312\Lib\site-packages\pandas\core\groupby\ops.py", line 864, in agg_series
    result = self._aggregate_series_pure_python(obj, func)
             ^^^^^^^^^^^^^^^^^^^^^^^^^^^^^^^^^^^^^^^^^^^^^
  File "c:\Users\miqueias.silva\AppData\Local\Programs\Python\Python312\Lib\site-packages\pandas\core\groupby\ops.py", line 885, in _aggregate_series_pure_python
    res = func(group)
          ^^^^^^^^^^^
  File "c:\Users\miqueias.silva\AppData\Local\Programs\Python\Python312\Lib\site-packages\pandas\core\groupby\generic.py", line 324, in <lambda>
    f = lambda x: func(x, *args, **kwargs)
                  ^^^^^^^^^^^^^^^^^^^^^^^^
  File "C:\Users\miqueias.silva\Documents\HADES\main.py", line 601, in <lambda>
    "OPERADOR": lambda x: "/".join(sorted(set(x)))
                          ^^^^^^^^^^^^^^^^^^^^^^^^
TypeError: sequence item 0: expected str instance, float found

During handling of the above exception, another exception occurred:

Traceback (most recent call last):
  File "C:\Users\miqueias.silva\Documents\HADES\main.py", line 533, in processor
    self.process_excel_file(file_path, inventory_name)
  File "C:\Users\miqueias.silva\Documents\HADES\main.py", line 613, in process_excel_file
    raise ValueError(f"Erro ao processar dados: {str(e)}")
ValueError: Erro ao processar dados: sequence item 0: expected str instance, float found

